Workbook

Sheet INICIO
A1: CANDYSHOTS — SISTEMA DE ADMINISTRACION
A2: Machala, Ecuador · v1.0 · Todos los valores en USD
B4: PARAMETROS GLOBALES | D4: Cambia estos valores y TODO el sistema se recalcula.
B5: IVA de venta (Ecuador 2026) | C5: 0.15 | D5: Tarifa vigente. Tus precios de carta se asumen CON IVA incluido.
B6: ¿Recuperas el IVA de tus compras? (SI/NO) | C6: SI | D6: CONFIRMADO 2026-09-07: SI. Regimen general con RUC, credito tributario. Si eso cambia, ponlo en NO.
B7: Dias de operacion al mes | C7: 26 | D7: Se usa para punto de equilibrio y proyecciones.
B8: Mes que analiza el DASHBOARD (AAAA-MM) | C8: 2026-09 | D8: Escribe el mes que quieres ver. Ej: 2026-10
B9: Margen objetivo por defecto | C9: 0.7 | D9: Se usa para calcular el PVP sugerido de productos nuevos.
B11: COMO USAR ESTE ARCHIVO
B12: Colores | D12: AZUL = escribes tu. NEGRO = formula, no tocar. VERDE = viene de otra hoja. FONDO AMARILLO = celda para llenar.
B14: ORDEN DE LLENADO (primera vez)
B15: 1. INSUMOS | D15: Cada cosa que compras: precio y cuanto rinde. Es la base de todo.
B16: 2. RECETAS | D16: Que insumos y cuanta cantidad lleva cada producto.
B17: 3. PRODUCTOS | D17: Precio de venta al publico. Te dice utilidad, margen y si el precio esta bien.
B18: 4. COMBOS | D18: Arma combos y ve cuanto margen sacrificas antes de lanzarlos.
B19: 5. GASTOS_FIJOS | D19: Arriendo, luz, sueldos. Alimenta el punto de equilibrio.
B21: USO DIARIO
B22: VENTAS | D22: Una fila por venta. Elige producto del desplegable y pon la cantidad. El resto se calcula solo.
B23: GASTOS | D23: Cada compra o pago que sale del negocio.
B24: CAJA | D24: Al cerrar el dia: cuanto habia, cuanto contaste. Te muestra el descuadre.
B26: SOLO LECTURA (no escribes nada)
B27: DASHBOARD | D27: Resumen del mes: venta, utilidad, top productos, alertas.
B28: EQUILIBRIO | D28: Cuantos vasos al dia necesitas para no perder plata. El numero mas importante.
B29: PYG | D29: Estado de resultados mes a mes con datos reales.
B30: PROYECCIONES | D30: 3 escenarios a 12 meses.
B31: INVENTARIO | D31: Stock y alertas de compra.
B33: REGLA DE ORO
D34: Si no registras las ventas todos los dias, este archivo no sirve para nada. 2 minutos al cierre.
B36: COMO ESTA CONECTADO TODO | D36: Cambias UN dato y se recalcula toda la cadena. Nunca escribas dos veces lo mismo.
B37: INSUMOS -> RECETAS | D37: Eliges el insumo de una LISTA. Trae solo su costo por ml/g/unidad.
B38: RECETAS -> PRODUCTOS | D38: Suma todas las lineas de la receta = costo del producto.
B39: PRODUCTOS -> COMBOS | D39: Eliges los items del combo de una LISTA. Trae precio y costo de cada uno.
B40: COMBOS -> PRODUCTOS | D40: El combo vuelve como un producto mas, para poder venderlo en VENTAS.
B41: PRODUCTOS -> VENTAS | D41: Eliges el producto de una LISTA. Trae precio Y costo. Tu solo pones la cantidad.
B42: VENTAS -> CAJA / DASHBOARD / PYG / EQUILIBRIO | D42: Todo el analisis sale de aqui. Por eso registrar ventas no es opcional.
B43: VENTAS + RECETAS -> INVENTARIO | D43: Calcula solo cuanto insumo consumiste segun lo que vendiste.
B44: GASTOS -> CAJA / DASHBOARD / PYG | D44: Los gastos reales bajan tu utilidad en todos los reportes.
B45: GASTOS_FIJOS -> EQUILIBRIO / PROYECCIONES | D45: Tu plan de fijos. Define cuantos vasos al dia necesitas vender.
B46: INSUMOS -> FICHAS_TECNICAS | D46: El costo impreso en la ficha se actualiza solo si sube un precio.
B48: SI ALGO NO TE APARECE EN UN DESPLEGABLE
...

Sheet DASHBOARD
A1: DASHBOARD
A2: Cambia el mes en la hoja INICIO (celda C8) y todo aqui se actualiza.
B3: MES ANALIZADO: | C3: =INICIO!$C$8
E4: RENDIMIENTO POR PRODUCTO (mes analizado)
B5: VENTA BRUTA DEL MES (c/IVA) | C5: =SUMIFS(VENTAS!$F$5:$F$504,VENTAS!$B$5:$B$504,INICIO!$C$8) | E5: Producto | F5: Unidades | G5: Venta c/IVA | H5: Utilidad
B6: IVA cobrado (esto NO es tuyo) | C6: =SUMIFS(VENTAS!$G$5:$G$504,VENTAS!$B$5:$B$504,INICIO!$C$8) | E6: =IF(PRODUCTOS!$B5="","",PRODUCTOS!$B5) | F6: =IF($E6="","",SUMIFS(VENTAS!$D$5:$D$504,VENTAS!$B$5:$B$504,INICIO!$C$8,VENTAS!$C$5:$C$504,$E6)) | G6: =IF($E6="","",SUMIFS(VENTAS!$F$5:$F$504,VENTAS!$B$5:$B$504,INICIO!$C$8,VENTAS!$C$5:$C$504,$E6)) | H6: =IF($E6="","",SUMIFS(VENTAS!$J$5:$J$504,VENTAS!$B$5:$B$504,INICIO!$C$8,VENTAS!$C$5:$C$504,$E6))
B7: INGRESO NETO (tuyo) | C7: =SUMIFS(VENTAS!$H$5:$H$504,VENTAS!$B$5:$B$504,INICIO!$C$8) | E7: =IF(PRODUCTOS!$B6="","",PRODUCTOS!$B6) | F7: =IF($E7="","",SUMIFS(VENTAS!$D$5:$D$504,VENTAS!$B$5:$B$504,INICIO!$C$8,VENTAS!$C$5:$C$504,$E7)) | G7: =IF($E7="","",SUMIFS(VENTAS!$F$5:$F$504,VENTAS!$B$5:$B$504,INICIO!$C$8,VENTAS!$C$5:$C$504,$E7)) | H7: =IF($E7="","",SUMIFS(VENTAS!$J$5:$J$504,VENTAS!$B$5:$B$504,INICIO!$C$8,VENTAS!$C$5:$C$504,$E7))
B8: Costo de ventas | C8: =SUMIFS(VENTAS!$I$5:$I$504,VENTAS!$B$5:$B$504,INICIO!$C$8) | E8: =IF(PRODUCTOS!$B7="","",PRODUCTOS!$B7) | F8: =IF($E8="","",SUMIFS(VENTAS!$D$5:$D$504,VENTAS!$B$5:$B$504,INICIO!$C$8,VENTAS!$C$5:$C$504,$E8)) | G8: =IF($E8="","",SUMIFS(VENTAS!$F$5:$F$504,VENTAS!$B$5:$B$504,INICIO!$C$8,VENTAS!$C$5:$C$504,$E8)) | H8: =IF($E8="","",SUMIFS(VENTAS!$J$5:$J$504,VENTAS!$B$5:$B$504,INICIO!$C$8,VENTAS!$C$5:$C$504,$E8))
B9: UTILIDAD BRUTA | C9: =$C$7-$C$8 | E9: =IF(PRODUCTOS!$B8="","",PRODUCTOS!$B8) | F9: =IF($E9="","",SUMIFS(VENTAS!$D$5:$D$504,VENTAS!$B$5:$B$504,INICIO!$C$8,VENTAS!$C$5:$C$504,$E9)) | G9: =IF($E9="","",SUMIFS(VENTAS!$F$5:$F$504,VENTAS!$B$5:$B$504,INICIO!$C$8,VENTAS!$C$5:$C$504,$E9)) | H9: =IF($E9="","",SUMIFS(VENTAS!$J$5:$J$504,VENTAS!$B$5:$B$504,INICIO!$C$8,VENTAS!$C$5:$C$504,$E9))
B10: Margen bruto | C10: =IFERROR($C$9/$C$7,0) | E10: =IF(PRODUCTOS!$B9="","",PRODUCTOS!$B9) | F10: =IF($E10="","",SUMIFS(VENTAS!$D$5:$D$504,VENTAS!$B$5:$B$504,INICIO!$C$8,VENTAS!$C$5:$C$504,$E10)) | G10: =IF($E10="","",SUMIFS(VENTAS!$F$5:$F$504,VENTAS!$B$5:$B$504,INICIO!$C$8,VENTAS!$C$5:$C$504,$E10)) | H10: =IF($E10="","",SUMIFS(VENTAS!$J$5:$J$504,VENTAS!$B$5:$B$504,INICIO!$C$8,VENTAS!$C$5:$C$504,$E10))
B11: Gastos operativos del mes | C11: =SUMIFS(GASTOS!$E$5:$E$304,GASTOS!$B$5:$B$304,INICIO!$C$8)-SUMIFS(GASTOS!$E$5:$E$304,GASTOS!$B$5:$B$304,INICIO!$C$8,GASTOS!$C$5:$C$304,"Insumos")-SUMIFS(GASTOS!$E$5:$E$304,GASTOS!$B$5:$B$304,INICIO!$C$8,GASTOS!$C$5:$C$304,"Descartables") | E11: =IF(PRODUCTOS!$B10="","",PRODUCTOS!$B10) | F11: =IF($E11="","",SUMIFS(VENTAS!$D$5:$D$504,VENTAS!$B$5:$B$504,INICIO!$C$8,VENTAS!$C$5:$C$504,$E11)) | G11: =IF($E11="","",SUMIFS(VENTAS!$F$5:$F$504,VENTAS!$B$5:$B$504,INICIO!$C$8,VENTAS!$C$5:$C$504,$E11)) | H11: =IF($E11="","",SUMIFS(VENTAS!$J$5:$J$504,VENTAS!$B$5:$B$504,INICIO!$C$8,VENTAS!$C$5:$C$504,$E11))
B12: UTILIDAD NETA DEL MES | C12: =$C$9-$C$11 | E12: =IF(PRODUCTOS!$B11="","",PRODUCTOS!$B11) | F12: =IF($E12="","",SUMIFS(VENTAS!$D$5:$D$504,VENTAS!$B$5:$B$504,INICIO!$C$8,VENTAS!$C$5:$C$504,$E12)) | G12: =IF($E12="","",SUMIFS(VENTAS!$F$5:$F$504,VENTAS!$B$5:$B$504,INICIO!$C$8,VENTAS!$C$5:$C$504,$E12)) | H12: =IF($E12="","",SUMIFS(VENTAS!$J$5:$J$504,VENTAS!$B$5:$B$504,INICIO!$C$8,VENTAS!$C$5:$C$504,$E12))
B13: Unidades vendidas | C13: =SUMIFS(VENTAS!$D$5:$D$504,VENTAS!$B$5:$B$504,INICIO!$C$8) | E13: =IF(PRODUCTOS!$B12="","",PRODUCTOS!$B12) | F13: =IF($E13="","",SUMIFS(VENTAS!$D$5:$D$504,VENTAS!$B$5:$B$504,INICIO!$C$8,VENTAS!$C$5:$C$504,$E13)) | G13: =IF($E13="","",SUMIFS(VENTAS!$F$5:$F$504,VENTAS!$B$5:$B$504,INICIO!$C$8,VENTAS!$C$5:$C$504,$E13)) | H13: =IF($E13="","",SUMIFS(VENTAS!$J$5:$J$504,VENTAS!$B$5:$B$504,INICIO!$C$8,VENTAS!$C$5:$C$504,$E13))
B14: Ticket promedio (c/IVA) | C14: =IFERROR($C$5/$C$13,0) | E14: =IF(PRODUCTOS!$B13="","",PRODUCTOS!$B13) | F14: =IF($E14="","",SUMIFS(VENTAS!$D$5:$D$504,VENTAS!$B$5:$B$504,INICIO!$C$8,VENTAS!$C$5:$C$504,$E14)) | G14: =IF($E14="","",SUMIFS(VENTAS!$F$5:$F$504,VENTAS!$B$5:$B$504,INICIO!$C$8,VENTAS!$C$5:$C$504,$E14)) | H14: =IF($E14="","",SUMIFS(VENTAS!$J$5:$J$504,VENTAS!$B$5:$B$504,INICIO!$C$8,VENTAS!$C$5:$C$504,$E14))
B15: Venta promedio por dia (mes / dias operacion) | C15: =IFERROR($C$5/INICIO!$C$7,0) | E15: =IF(PRODUCTOS!$B14="","",PRODUCTOS!$B14) | F15: =IF($E15="","",SUMIFS(VENTAS!$D$5:$D$504,VENTAS!$B$5:$B$504,INICIO!$C$8,VENTAS!$C$5:$C$504,$E15)) | G15: =IF($E15="","",SUMIFS(VENTAS!$F$5:$F$504,VENTAS!$B$5:$B$504,INICIO!$C$8,VENTAS!$C$5:$C$504,$E15)) | H15: =IF($E15="","",SUMIFS(VENTAS!$J$5:$J$504,VENTAS!$B$5:$B$504,INICIO!$C$8,VENTAS!$C$5:$C$504,$E15))
E16: =IF(PRODUCTOS!$B15="","",PRODUCTOS!$B15) | F16: =IF($E16="","",SUMIFS(VENTAS!$D$5:$D$504,VENTAS!$B$5:$B$504,INICIO!$C$8,VENTAS!$C$5:$C$504,$E16)) | G16: =IF($E16="","",SUMIFS(VENTAS!$F$5:$F$504,VENTAS!$B$5:$B$504,INICIO!$C$8,VENTAS!$C$5:$C$504,$E16)) | H16: =IF($E16="","",SUMIFS(VENTAS!$J$5:$J$504,VENTAS!$B$5:$B$504,INICIO!$C$8,VENTAS!$C$5:$C$504,$E16))
B17: VS PUNTO DE EQUILIBRIO | E17: =IF(PRODUCTOS!$B16="","",PRODUCTOS!$B16) | F17: =IF($E17="","",SUMIFS(VENTAS!$D$5:$D$504,VENTAS!$B$5:$B$504,INICIO!$C$8,VENTAS!$C$5:$C$504,$E17)) | G17: =IF($E17="","",SUMIFS(VENTAS!$F$5:$F$504,VENTAS!$B$5:$B$504,INICIO!$C$8,VENTAS!$C$5:$C$504,$E17)) | H17: =IF($E17="","",SUMIFS(VENTAS!$J$5:$J$504,VENTAS!$B$5:$B$504,INICIO!$C$8,VENTAS!$C$5:$C$504,$E17))
B18: Unidades necesarias al mes | C18: =IFERROR(EQUILIBRIO!$C$18,0) | E18: =IF(PRODUCTOS!$B17="","",PRODUCTOS!$B17) | F18: =IF($E18="","",SUMIFS(VENTAS!$D$5:$D$504,VENTAS!$B$5:$B$504,INICIO!$C$8,VENTAS!$C$5:$C$504,$E18)) | G18: =IF($E18="","",SUMIFS(VENTAS!$F$5:$F$504,VENTAS!$B$5:$B$504,INICIO!$C$8,VENTAS!$C$5:$C$504,$E18)) | H18: =IF($E18="","",SUMIFS(VENTAS!$J$5:$J$504,VENTAS!$B$5:$B$504,INICIO!$C$8,VENTAS!$C$5:$C$504,$E18))
B19: % del punto de equilibrio alcanzado | C19: =IFERROR($C$13/EQUILIBRIO!$C$18,0) | E19: =IF(PRODUCTOS!$B18="","",PRODUCTOS!$B18) | F19: =IF($E19="","",SUMIFS(VENTAS!$D$5:$D$504,VENTAS!$B$5:$B$504,INICIO!$C$8,VENTAS!$C$5:$C$504,$E19)) | G19: =IF($E19="","",SUMIFS(VENTAS!$F$5:$F$504,VENTAS!$B$5:$B$504,INICIO!$C$8,VENTAS!$C$5:$C$504,$E19)) | H19: =IF($E19="","",SUMIFS(VENTAS!$J$5:$J$504,VENTAS!$B$5:$B$504,INICIO!$C$8,VENTAS!$C$5:$C$504,$E19))
B20: Estado | C20: =IF($C$12>0,"GANANDO PLATA",IF($C$13=0,"SIN DATOS","PERDIENDO PLATA")) | E20: =IF(PRODUCTOS!$B19="","",PRODUCTOS!$B19) | F20: =IF($E20="","",SUMIFS(VENTAS!$D$5:$D$504,VENTAS!$B$5:$B$504,INICIO!$C$8,VENTAS!$C$5:$C$504,$E20)) | G20: =IF($E20="","",SUMIFS(VENTAS!$F$5:$F$504,VENTAS!$B$5:$B$504,INICIO!$C$8,VENTAS!$C$5:$C$504,$E20)) | H20: =IF($E20="","",SUMIFS(VENTAS!$J$5:$J$504,VENTAS!$B$5:$B$504,INICIO!$C$8,VENTAS!$C$5:$C$504,$E20))
E21: =IF(PRODUCTOS!$B20="","",PRODUCTOS!$B20) | F21: =IF($E21="","",SUMIFS(VENTAS!$D$5:$D$504,VENTAS!$B$5:$B$504,INICIO!$C$8,VENTAS!$C$5:$C$504,$E21)) | G21: =IF($E21="","",SUMIFS(VENTAS!$F$5:$F$504,VENTAS!$B$5:$B$504,INICIO!$C$8,VENTAS!$C$5:$C$504,$E21)) | H21: =IF($E21="","",SUMIFS(VENTAS!$J$5:$J$504,VENTAS!$B$5:$B$504,INICIO!$C$8,VENTAS!$C$5:$C$504,$E21))
E22: =IF(PRODUCTOS!$B21="","",PRODUCTOS!$B21) | F22: =IF($E22="","",SUMIFS(VENTAS!$D$5:$D$504,VENTAS!$B$5:$B$504,INICIO!$C$8,VENTAS!$C$5:$C$504,$E22)) | G22: =IF($E22="","",SUMIFS(VENTAS!$F$5:$F$504,VENTAS!$B$5:$B$504,INICIO!$C$8,VENTAS!$C$5:$C$504,$E22)) | H22: =IF($E22="","",SUMIFS(VENTAS!$J$5:$J$504,VENTAS!$B$5:$B$504,INICIO!$C$8,VENTAS!$C$5:$C$504,$E22))
E23: =IF(PRODUCTOS!$B22="","",PRODUCTOS!$B22) | F23: =IF($E23="","",SUMIFS(VENTAS!$D$5:$D$504,VENTAS!$B$5:$B$504,INICIO!$C$8,VENTAS!$C$5:$C$504,$E23)) | G23: =IF($E23="","",SUMIFS(VENTAS!$F$5:$F$504,VENTAS!$B$5:$B$504,INICIO!$C$8,VENTAS!$C$5:$C$504,$E23)) | H23: =IF($E23="","",SUMIFS(VENTAS!$J$5:$J$504,VENTAS!$B$5:$B$504,INICIO!$C$8,VENTAS!$C$5:$C$504,$E23))
E24: =IF(PRODUCTOS!$B23="","",PRODUCTOS!$B23) | F24: =IF($E24="","",SUMIFS(VENTAS!$D$5:$D$504,VENTAS!$B$5:$B$504,INICIO!$C$8,VENTAS!$C$5:$C$504,$E24)) | G24: =IF($E24="","",SUMIFS(VENTAS!$F$5:$F$504,VENTAS!$B$5:$B$504,INICIO!$C$8,VENTAS!$C$5:$C$504,$E24)) | H24: =IF($E24="","",SUMIFS(VENTAS!$J$5:$J$504,VENTAS!$B$5:$B$504,INICIO!$C$8,VENTAS!$C$5:$C$504,$E24))
E25: =IF(PRODUCTOS!$B24="","",PRODUCTOS!$B24) | F25: =IF($E25="","",SUMIFS(VENTAS!$D$5:$D$504,VENTAS!$B$5:$B$504,INICIO!$C$8,VENTAS!$C$5:$C$504,$E25)) | G25: =IF($E25="","",SUMIFS(VENTAS!$F$5:$F$504,VENTAS!$B$5:$B$504,INICIO!$C$8,VENTAS!$C$5:$C$504,$E25)) | H25: =IF($E25="","",SUMIFS(VENTAS!$J$5:$J$504,VENTAS!$B$5:$B$504,INICIO!$C$8,VENTAS!$C$5:$C$504,$E25))
E26: =IF(PRODUCTOS!$B25="","",PRODUCTOS!$B25) | F26: =IF($E26="","",SUMIFS(VENTAS!$D$5:$D$504,VENTAS!$B$5:$B$504,INICIO!$C$8,VENTAS!$C$5:$C$504,$E26)) | G26: =IF($E26="","",SUMIFS(VENTAS!$F$5:$F$504,VENTAS!$B$5:$B$504,INICIO!$C$8,VENTAS!$C$5:$C$504,$E26)) | H26: =IF($E26="","",SUMIFS(VENTAS!$J$5:$J$504,VENTAS!$B$5:$B$504,INICIO!$C$8,VENTAS!$C$5:$C$504,$E26))
E27: =IF(PRODUCTOS!$B26="","",PRODUCTOS!$B26) | F27: =IF($E27="","",SUMIFS(VENTAS!$D$5:$D$504,VENTAS!$B$5:$B$504,INICIO!$C$8,VENTAS!$C$5:$C$504,$E27)) | G27: =IF($E27="","",SUMIFS(VENTAS!$F$5:$F$504,VENTAS!$B$5:$B$504,INICIO!$C$8,VENTAS!$C$5:$C$504,$E27)) | H27: =IF($E27="","",SUMIFS(VENTAS!$J$5:$J$504,VENTAS!$B$5:$B$504,INICIO!$C$8,VENTAS!$C$5:$C$504,$E27))
E28: =IF(PRODUCTOS!$B27="","",PRODUCTOS!$B27) | F28: =IF($E28="","",SUMIFS(VENTAS!$D$5:$D$504,VENTAS!$B$5:$B$504,INICIO!$C$8,VENTAS!$C$5:$C$504,$E28)) | G28: =IF($E28="","",SUMIFS(VENTAS!$F$5:$F$504,VENTAS!$B$5:$B$504,INICIO!$C$8,VENTAS!$C$5:$C$504,$E28)) | H28: =IF($E28="","",SUMIFS(VENTAS!$J$5:$J$504,VENTAS!$B$5:$B$504,INICIO!$C$8,VENTAS!$C$5:$C$504,$E28))
E29: =IF(PRODUCTOS!$B28="","",PRODUCTOS!$B28) | F29: =IF($E29="","",SUMIFS(VENTAS!$D$5:$D$504,VENTAS!$B$5:$B$504,INICIO!$C$8,VENTAS!$C$5:$C$504,$E29)) | G29: =IF($E29="","",SUMIFS(VENTAS!$F$5:$F$504,VENTAS!$B$5:$B$504,INICIO!$C$8,VENTAS!$C$5:$C$504,$E29)) | H29: =IF($E29="","",SUMIFS(VENTAS!$J$5:$J$504,VENTAS!$B$5:$B$504,INICIO!$C$8,VENTAS!$C$5:$C$504,$E29))
E30: =IF(PRODUCTOS!$B29="","",PRODUCTOS!$B29) | F30: =IF($E30="","",SUMIFS(VENTAS!$D$5:$D$504,VENTAS!$B$5:$B$504,INICIO!$C$8,VENTAS!$C$5:$C$504,$E30)) | G30: =IF($E30="","",SUMIFS(VENTAS!$F$5:$F$504,VENTAS!$B$5:$B$504,INICIO!$C$8,VENTAS!$C$5:$C$504,$E30)) | H30: =IF($E30="","",SUMIFS(VENTAS!$J$5:$J$504,VENTAS!$B$5:$B$504,INICIO!$C$8,VENTAS!$C$5:$C$504,$E30))
E31: =IF(PRODUCTOS!$B30="","",PRODUCTOS!$B30) | F31: =IF($E31="","",SUMIFS(VENTAS!$D$5:$D$504,VENTAS!$B$5:$B$504,INICIO!$C$8,VENTAS!$C$5:$C$504,$E31)) | G31: =IF($E31="","",SUMIFS(VENTAS!$F$5:$F$504,VENTAS!$B$5:$B$504,INICIO!$C$8,VENTAS!$C$5:$C$504,$E31)) | H31: =IF($E31="","",SUMIFS(VENTAS!$J$5:$J$504,VENTAS!$B$5:$B$504,INICIO!$C$8,VENTAS!$C$5:$C$504,$E31))
E32: =IF(PRODUCTOS!$B31="","",PRODUCTOS!$B31) | F32: =IF($E32="","",SUMIFS(VENTAS!$D$5:$D$504,VENTAS!$B$5:$B$504,INICIO!$C$8,VENTAS!$C$5:$C$504,$E32)) | G32: =IF($E32="","",SUMIFS(VENTAS!$F$5:$F$504,VENTAS!$B$5:$B$504,INICIO!$C$8,VENTAS!$C$5:$C$504,$E32)) | H32: =IF($E32="","",SUMIFS(VENTAS!$J$5:$J$504,VENTAS!$B$5:$B$504,INICIO!$C$8,VENTAS!$C$5:$C$504,$E32))
... E45: =IF(PRODUCTOS!$B44="","",PRODUCTOS!$B44) | F45: =IF($E45="","",SUMIFS(VENTAS!$D$5:$D$504,VENTAS!$B$5:$B$504,INICIO!$C$8,VENTAS!$C$5:$C$504,$E45)) | G45: =IF($E45="","",SUMIFS(VENTAS!$F$5:$F$504,VENTAS!$B$5:$B$504,INICIO!$C$8,VENTAS!$C$5:$C$504,$E45)) | H45: =IF($E45="","",SUMIFS(VENTAS!$J$5:$J$504,VENTAS!$B$5:$B$504,INICIO!$C$8,VENTAS!$C$5:$C$504,$E45))
E47: Ordena esta tabla por 'Utilidad' (Datos > Ordenar) para ver que producto realmente te da de comer.
E48: El que mas vende no siempre es el que mas deja. Ese es el punto de esta tabla.

Sheet VENTAS
A1: VENTAS
A2: Una fila por venta. Solo llenas: Fecha · Producto · Cantidad · Forma de pago · Atendio. El resto se calcula solo.
A4: Fecha | B4: Mes | C4: Producto | D4: Cant. | E4: PVP unit c/IVA | F4: TOTAL c/IVA | G4: IVA cobrado | H4: Ingreso neto | I4: Costo | J4: UTILIDAD | K4: Forma de pago | L4: Atendio
A5: 46280 | B5: =IF($A5="","",TEXT($A5,"YYYY-MM")) | C5: Coco s/alcohol | D5: 2 | E5: =IFERROR(IF($C5="","",INDEX(PRODUCTOS!$E$5:$E$44,MATCH($C5,PRODUCTOS!$B$5:$B$44,0))),"") | F5: =IFERROR(IF($C5="","",$D5*$E5),"") | G5: =IFERROR(IF($C5="","",$F5-$H5),"") | H5: =IFERROR(IF($C5="","",$F5/(1+INICIO!$C$5)),"") | I5: =IFERROR(IF($C5="","",$D5*INDEX(PRODUCTOS!$D$5:$D$44,MATCH($C5,PRODUCTOS!$B$5:$B$44,0))),"") | J5: =IFERROR(IF($C5="","",$H5-$I5),"") | K5: Efectivo | L5: Fabian
B6: =IF($A6="","",TEXT($A6,"YYYY-MM")) | E6: =IFERROR(IF($C6="","",INDEX(PRODUCTOS!$E$5:$E$44,MATCH($C6,PRODUCTOS!$B$5:$B$44,0))),"") | F6: =IFERROR(IF($C6="","",$D6*$E6),"") | G6: =IFERROR(IF($C6="","",$F6-$H6),"") | H6: =IFERROR(IF($C6="","",$F6/(1+INICIO!$C$5)),"") | I6: =IFERROR(IF($C6="","",$D6*INDEX(PRODUCTOS!$D$5:$D$44,MATCH($C6,PRODUCTOS!$B$5:$B$44,0))),"") | J6: =IFERROR(IF($C6="","",$H6-$I6),"")
B7: =IF($A7="","",TEXT($A7,"YYYY-MM")) | E7: =IFERROR(IF($C7="","",INDEX(PRODUCTOS!$E$5:$E$44,MATCH($C7,PRODUCTOS!$B$5:$B$44,0))),"") | F7: =IFERROR(IF($C7="","",$D7*$E7),"") | G7: =IFERROR(IF($C7="","",$F7-$H7),"") | H7: =IFERROR(IF($C7="","",$F7/(1+INICIO!$C$5)),"") | I7: =IFERROR(IF($C7="","",$D7*INDEX(PRODUCTOS!$D$5:$D$44,MATCH($C7,PRODUCTOS!$B$5:$B$44,0))),"") | J7: =IFERROR(IF($C7="","",$H7-$I7),"")
B8: =IF($A8="","",TEXT($A8,"YYYY-MM")) | E8: =IFERROR(IF($C8="","",INDEX(PRODUCTOS!$E$5:$E$44,MATCH($C8,PRODUCTOS!$B$5:$B$44,0))),"") | F8: =IFERROR(IF($C8="","",$D8*$E8),"") | G8: =IFERROR(IF($C8="","",$F8-$H8),"") | H8: =IFERROR(IF($C8="","",$F8/(1+INICIO!$C$5)),"") | I8: =IFERROR(IF($C8="","",$D8*INDEX(PRODUCTOS!$D$5:$D$44,MATCH($C8,PRODUCTOS!$B$5:$B$44,0))),"") | J8: =IFERROR(IF($C8="","",$H8-$I8),"")
B9: =IF($A9="","",TEXT($A9,"YYYY-MM")) | E9: =IFERROR(IF($C9="","",INDEX(PRODUCTOS!$E$5:$E$44,MATCH($C9,PRODUCTOS!$B$5:$B$44,0))),"") | F9: =IFERROR(IF($C9="","",$D9*$E9),"") | G9: =IFERROR(IF($C9="","",$F9-$H9),"") | H9: =IFERROR(IF($C9="","",$F9/(1+INICIO!$C$5)),"") | I9: =IFERROR(IF($C9="","",$D9*INDEX(PRODUCTOS!$D$5:$D$44,MATCH($C9,PRODUCTOS!$B$5:$B$44,0))),"") | J9: =IFERROR(IF($C9="","",$H9-$I9),"")
B10: =IF($A10="","",TEXT($A10,"YYYY-MM")) | E10: =IFERROR(IF($C10="","",INDEX(PRODUCTOS!$E$5:$E$44,MATCH($C10,PRODUCTOS!$B$5:$B$44,0))),"") | F10: =IFERROR(IF($C10="","",$D10*$E10),"") | G10: =IFERROR(IF($C10="","",$F10-$H10),"") | H10: =IFERROR(IF($C10="","",$F10/(1+INICIO!$C$5)),"") | I10: =IFERROR(IF($C10="","",$D10*INDEX(PRODUCTOS!$D$5:$D$44,MATCH($C10,PRODUCTOS!$B$5:$B$44,0))),"") | J10: =IFERROR(IF($C10="","",$H10-$I10),"")
B11: =IF($A11="","",TEXT($A11,"YYYY-MM")) | E11: =IFERROR(IF($C11="","",INDEX(PRODUCTOS!$E$5:$E$44,MATCH($C11,PRODUCTOS!$B$5:$B$44,0))),"") | F11: =IFERROR(IF($C11="","",$D11*$E11),"") | G11: =IFERROR(IF($C11="","",$F11-$H11),"") | H11: =IFERROR(IF($C11="","",$F11/(1+INICIO!$C$5)),"") | I11: =IFERROR(IF($C11="","",$D11*INDEX(PRODUCTOS!$D$5:$D$44,MATCH($C11,PRODUCTOS!$B$5:$B$44,0))),"") | J11: =IFERROR(IF($C11="","",$H11-$I11),"")
B12: =IF($A12="","",TEXT($A12,"YYYY-MM")) | E12: =IFERROR(IF($C12="","",INDEX(PRODUCTOS!$E$5:$E$44,MATCH($C12,PRODUCTOS!$B$5:$B$44,0))),"") | F12: =IFERROR(IF($C12="","",$D12*$E12),"") | G12: =IFERROR(IF($C12="","",$F12-$H12),"") | H12: =IFERROR(IF($C12="","",$F12/(1+INICIO!$C$5)),"") | I12: =IFERROR(IF($C12="","",$D12*INDEX(PRODUCTOS!$D$5:$D$44,MATCH($C12,PRODUCTOS!$B$5:$B$44,0))),"") | J12: =IFERROR(IF($C12="","",$H12-$I12),"")
B13: =IF($A13="","",TEXT($A13,"YYYY-MM")) | E13: =IFERROR(IF($C13="","",INDEX(PRODUCTOS!$E$5:$E$44,MATCH($C13,PRODUCTOS!$B$5:$B$44,0))),"") | F13: =IFERROR(IF($C13="","",$D13*$E13),"") | G13: =IFERROR(IF($C13="","",$F13-$H13),"") | H13: =IFERROR(IF($C13="","",$F13/(1+INICIO!$C$5)),"") | I13: =IFERROR(IF($C13="","",$D13*INDEX(PRODUCTOS!$D$5:$D$44,MATCH($C13,PRODUCTOS!$B$5:$B$44,0))),"") | J13: =IFERROR(IF($C13="","",$H13-$I13),"")
B14: =IF($A14="","",TEXT($A14,"YYYY-MM")) | E14: =IFERROR(IF($C14="","",INDEX(PRODUCTOS!$E$5:$E$44,MATCH($C14,PRODUCTOS!$B$5:$B$44,0))),"") | F14: =IFERROR(IF($C14="","",$D14*$E14),"") | G14: =IFERROR(IF($C14="","",$F14-$H14),"") | H14: =IFERROR(IF($C14="","",$F14/(1+INICIO!$C$5)),"") | I14: =IFERROR(IF($C14="","",$D14*INDEX(PRODUCTOS!$D$5:$D$44,MATCH($C14,PRODUCTOS!$B$5:$B$44,0))),"") | J14: =IFERROR(IF($C14="","",$H14-$I14),"")
B15: =IF($A15="","",TEXT($A15,"YYYY-MM")) | E15: =IFERROR(IF($C15="","",INDEX(PRODUCTOS!$E$5:$E$44,MATCH($C15,PRODUCTOS!$B$5:$B$44,0))),"") | F15: =IFERROR(IF($C15="","",$D15*$E15),"") | G15: =IFERROR(IF($C15="","",$F15-$H15),"") | H15: =IFERROR(IF($C15="","",$F15/(1+INICIO!$C$5)),"") | I15: =IFERROR(IF($C15="","",$D15*INDEX(PRODUCTOS!$D$5:$D$44,MATCH($C15,PRODUCTOS!$B$5:$B$44,0))),"") | J15: =IFERROR(IF($C15="","",$H15-$I15),"")
B16: =IF($A16="","",TEXT($A16,"YYYY-MM")) | E16: =IFERROR(IF($C16="","",INDEX(PRODUCTOS!$E$5:$E$44,MATCH($C16,PRODUCTOS!$B$5:$B$44,0))),"") | F16: =IFERROR(IF($C16="","",$D16*$E16),"") | G16: =IFERROR(IF($C16="","",$F16-$H16),"") | H16: =IFERROR(IF($C16="","",$F16/(1+INICIO!$C$5)),"") | I16: =IFERROR(IF($C16="","",$D16*INDEX(PRODUCTOS!$D$5:$D$44,MATCH($C16,PRODUCTOS!$B$5:$B$44,0))),"") | J16: =IFERROR(IF($C16="","",$H16-$I16),"")
B17: =IF($A17="","",TEXT($A17,"YYYY-MM")) | E17: =IFERROR(IF($C17="","",INDEX(PRODUCTOS!$E$5:$E$44,MATCH($C17,PRODUCTOS!$B$5:$B$44,0))),"") | F17: =IFERROR(IF($C17="","",$D17*$E17),"") | G17: =IFERROR(IF($C17="","",$F17-$H17),"") | H17: =IFERROR(IF($C17="","",$F17/(1+INICIO!$C$5)),"") | I17: =IFERROR(IF($C17="","",$D17*INDEX(PRODUCTOS!$D$5:$D$44,MATCH($C17,PRODUCTOS!$B$5:$B$44,0))),"") | J17: =IFERROR(IF($C17="","",$H17-$I17),"")
... B504: =IF($A504="","",TEXT($A504,"YYYY-MM")) | E504: =IFERROR(IF($C504="","",INDEX(PRODUCTOS!$E$5:$E$44,MATCH($C504,PRODUCTOS!$B$5:$B$44,0))),"") | F504: =IFERROR(IF($C504="","",$D504*$E504),"") | G504: =IFERROR(IF($C504="","",$F504-$H504),"") | H504: =IFERROR(IF($C504="","",$F504/(1+INICIO!$C$5)),"") | I504: =IFERROR(IF($C504="","",$D504*INDEX(PRODUCTOS!$D$5:$D$44,MATCH($C504,PRODUCTOS!$B$5:$B$44,0))),"") | J504: =IFERROR(IF($C504="","",$H504-$I504),"")

Sheet GASTOS
A1: GASTOS
A2: Todo lo que sale del negocio. Si no lo registras, tu utilidad es mentira.
A4: Fecha | B4: Mes | C4: Categoria | D4: Detalle / Proveedor | E4: Monto | F4: Tipo | G4: Forma de pago | H4: ¿Sale de caja?
A5: 46280 | B5: =IF($A5="","",TEXT($A5,"YYYY-MM")) | C5: Insumos | D5: Compra de jarabes - proveedor local | E5: 40 | F5: Variable | G5: Efectivo | H5: SI
B6: =IF($A6="","",TEXT($A6,"YYYY-MM"))
B7: =IF($A7="","",TEXT($A7,"YYYY-MM"))
B8: =IF($A8="","",TEXT($A8,"YYYY-MM"))
B9: =IF($A9="","",TEXT($A9,"YYYY-MM"))
B10: =IF($A10="","",TEXT($A10,"YYYY-MM"))
B11: =IF($A11="","",TEXT($A11,"YYYY-MM"))
B12: =IF($A12="","",TEXT($A12,"YYYY-MM"))
B13: =IF($A13="","",TEXT($A13,"YYYY-MM"))
B14: =IF($A14="","",TEXT($A14,"YYYY-MM"))
B15: =IF($A15="","",TEXT($A15,"YYYY-MM"))
B16: =IF($A16="","",TEXT($A16,"YYYY-MM"))
B17: =IF($A17="","",TEXT($A17,"YYYY-MM"))
... B304: =IF($A304="","",TEXT($A304,"YYYY-MM"))

Sheet CAJA
A1: CIERRE DE CAJA DIARIO
A2: Al cerrar: pon el fondo con el que abriste y cuenta el efectivo real. El descuadre te dice si algo se fue.
A4: Fecha | B4: Fondo apertura | C4: Ventas EFECTIVO | D4: Ventas TRANSFERENCIA | E4: Ventas PAYPHONE/Tarjeta | F4: Gastos en efectivo | G4: Retiros | H4: EFECTIVO TEORICO | I4: Efectivo contado | J4: DESCUADRE
A5: 46280 | B5: 20 | C5: =IF($A5="","",SUMIFS(VENTAS!$F$5:$F$504,VENTAS!$A$5:$A$504,$A5,VENTAS!$K$5:$K$504,"Efectivo")) | D5: =IF($A5="","",SUMIFS(VENTAS!$F$5:$F$504,VENTAS!$A$5:$A$504,$A5,VENTAS!$K$5:$K$504,"Transferencia")) | E5: =IF($A5="","",SUMIFS(VENTAS!$F$5:$F$504,VENTAS!$A$5:$A$504,$A5,VENTAS!$K$5:$K$504,"PayPhone")+SUMIFS(VENTAS!$F$5:$F$504,VENTAS!$A$5:$A$504,$A5,VENTAS!$K$5:$K$504,"Tarjeta")) | F5: =IF($A5="","",SUMIFS(GASTOS!$E$5:$E$304,GASTOS!$A$5:$A$304,$A5,GASTOS!$G$5:$G$304,"Efectivo",GASTOS!$H$5:$H$304,"SI")) | H5: =IF($A5="","",$B5+$C5-$F5-N($G5)) | J5: =IF($A5="","",IF($I5="","",$I5-$H5))
C6: =IF($A6="","",SUMIFS(VENTAS!$F$5:$F$504,VENTAS!$A$5:$A$504,$A6,VENTAS!$K$5:$K$504,"Efectivo")) | D6: =IF($A6="","",SUMIFS(VENTAS!$F$5:$F$504,VENTAS!$A$5:$A$504,$A6,VENTAS!$K$5:$K$504,"Transferencia")) | E6: =IF($A6="","",SUMIFS(VENTAS!$F$5:$F$504,VENTAS!$A$5:$A$504,$A6,VENTAS!$K$5:$K$504,"PayPhone")+SUMIFS(VENTAS!$F$5:$F$504,VENTAS!$A$5:$A$504,$A6,VENTAS!$K$5:$K$504,"Tarjeta")) | F6: =IF($A6="","",SUMIFS(GASTOS!$E$5:$E$304,GASTOS!$A$5:$A$304,$A6,GASTOS!$G$5:$G$304,"Efectivo",GASTOS!$H$5:$H$304,"SI")) | H6: =IF($A6="","",$B6+$C6-$F6-N($G6)) | J6: =IF($A6="","",IF($I6="","",$I6-$H6))
C7: =IF($A7="","",SUMIFS(VENTAS!$F$5:$F$504,VENTAS!$A$5:$A$504,$A7,VENTAS!$K$5:$K$504,"Efectivo")) | D7: =IF($A7="","",SUMIFS(VENTAS!$F$5:$F$504,VENTAS!$A$5:$A$504,$A7,VENTAS!$K$5:$K$504,"Transferencia")) | E7: =IF($A7="","",SUMIFS(VENTAS!$F$5:$F$504,VENTAS!$A$5:$A$504,$A7,VENTAS!$K$5:$K$504,"PayPhone")+SUMIFS(VENTAS!$F$5:$F$504,VENTAS!$A$5:$A$504,$A7,VENTAS!$K$5:$K$504,"Tarjeta")) | F7: =IF($A7="","",SUMIFS(GASTOS!$E$5:$E$304,GASTOS!$A$5:$A$304,$A7,GASTOS!$G$5:$G$304,"Efectivo",GASTOS!$H$5:$H$304,"SI")) | H7: =IF($A7="","",$B7+$C7-$F7-N($G7)) | J7: =IF($A7="","",IF($I7="","",$I7-$H7))
C8: =IF($A8="","",SUMIFS(VENTAS!$F$5:$F$504,VENTAS!$A$5:$A$504,$A8,VENTAS!$K$5:$K$504,"Efectivo")) | D8: =IF($A8="","",SUMIFS(VENTAS!$F$5:$F$504,VENTAS!$A$5:$A$504,$A8,VENTAS!$K$5:$K$504,"Transferencia")) | E8: =IF($A8="","",SUMIFS(VENTAS!$F$5:$F$504,VENTAS!$A$5:$A$504,$A8,VENTAS!$K$5:$K$504,"PayPhone")+SUMIFS(VENTAS!$F$5:$F$504,VENTAS!$A$5:$A$504,$A8,VENTAS!$K$5:$K$504,"Tarjeta")) | F8: =IF($A8="","",SUMIFS(GASTOS!$E$5:$E$304,GASTOS!$A$5:$A$304,$A8,GASTOS!$G$5:$G$304,"Efectivo",GASTOS!$H$5:$H$304,"SI")) | H8: =IF($A8="","",$B8+$C8-$F8-N($G8)) | J8: =IF($A8="","",IF($I8="","",$I8-$H8))
C9: =IF($A9="","",SUMIFS(VENTAS!$F$5:$F$504,VENTAS!$A$5:$A$504,$A9,VENTAS!$K$5:$K$504,"Efectivo")) | D9: =IF($A9="","",SUMIFS(VENTAS!$F$5:$F$504,VENTAS!$A$5:$A$504,$A9,VENTAS!$K$5:$K$504,"Transferencia")) | E9: =IF($A9="","",SUMIFS(VENTAS!$F$5:$F$504,VENTAS!$A$5:$A$504,$A9,VENTAS!$K$5:$K$504,"PayPhone")+SUMIFS(VENTAS!$F$5:$F$504,VENTAS!$A$5:$A$504,$A9,VENTAS!$K$5:$K$504,"Tarjeta")) | F9: =IF($A9="","",SUMIFS(GASTOS!$E$5:$E$304,GASTOS!$A$5:$A$304,$A9,GASTOS!$G$5:$G$304,"Efectivo",GASTOS!$H$5:$H$304,"SI")) | H9: =IF($A9="","",$B9+$C9-$F9-N($G9)) | J9: =IF($A9="","",IF($I9="","",$I9-$H9))
C10: =IF($A10="","",SUMIFS(VENTAS!$F$5:$F$504,VENTAS!$A$5:$A$504,$A10,VENTAS!$K$5:$K$504,"Efectivo")) | D10: =IF($A10="","",SUMIFS(VENTAS!$F$5:$F$504,VENTAS!$A$5:$A$504,$A10,VENTAS!$K$5:$K$504,"Transferencia")) | E10: =IF($A10="","",SUMIFS(VENTAS!$F$5:$F$504,VENTAS!$A$5:$A$504,$A10,VENTAS!$K$5:$K$504,"PayPhone")+SUMIFS(VENTAS!$F$5:$F$504,VENTAS!$A$5:$A$504,$A10,VENTAS!$K$5:$K$504,"Tarjeta")) | F10: =IF($A10="","",SUMIFS(GASTOS!$E$5:$E$304,GASTOS!$A$5:$A$304,$A10,GASTOS!$G$5:$G$304,"Efectivo",GASTOS!$H$5:$H$304,"SI")) | H10: =IF($A10="","",$B10+$C10-$F10-N($G10)) | J10: =IF($A10="","",IF($I10="","",$I10-$H10))
C11: =IF($A11="","",SUMIFS(VENTAS!$F$5:$F$504,VENTAS!$A$5:$A$504,$A11,VENTAS!$K$5:$K$504,"Efectivo")) | D11: =IF($A11="","",SUMIFS(VENTAS!$F$5:$F$504,VENTAS!$A$5:$A$504,$A11,VENTAS!$K$5:$K$504,"Transferencia")) | E11: =IF($A11="","",SUMIFS(VENTAS!$F$5:$F$504,VENTAS!$A$5:$A$504,$A11,VENTAS!$K$5:$K$504,"PayPhone")+SUMIFS(VENTAS!$F$5:$F$504,VENTAS!$A$5:$A$504,$A11,VENTAS!$K$5:$K$504,"Tarjeta")) | F11: =IF($A11="","",SUMIFS(GASTOS!$E$5:$E$304,GASTOS!$A$5:$A$304,$A11,GASTOS!$G$5:$G$304,"Efectivo",GASTOS!$H$5:$H$304,"SI")) | H11: =IF($A11="","",$B11+$C11-$F11-N($G11)) | J11: =IF($A11="","",IF($I11="","",$I11-$H11))
C12: =IF($A12="","",SUMIFS(VENTAS!$F$5:$F$504,VENTAS!$A$5:$A$504,$A12,VENTAS!$K$5:$K$504,"Efectivo")) | D12: =IF($A12="","",SUMIFS(VENTAS!$F$5:$F$504,VENTAS!$A$5:$A$504,$A12,VENTAS!$K$5:$K$504,"Transferencia")) | E12: =IF($A12="","",SUMIFS(VENTAS!$F$5:$F$504,VENTAS!$A$5:$A$504,$A12,VENTAS!$K$5:$K$504,"PayPhone")+SUMIFS(VENTAS!$F$5:$F$504,VENTAS!$A$5:$A$504,$A12,VENTAS!$K$5:$K$504,"Tarjeta")) | F12: =IF($A12="","",SUMIFS(GASTOS!$E$5:$E$304,GASTOS!$A$5:$A$304,$A12,GASTOS!$G$5:$G$304,"Efectivo",GASTOS!$H$5:$H$304,"SI")) | H12: =IF($A12="","",$B12+$C12-$F12-N($G12)) | J12: =IF($A12="","",IF($I12="","",$I12-$H12))
C13: =IF($A13="","",SUMIFS(VENTAS!$F$5:$F$504,VENTAS!$A$5:$A$504,$A13,VENTAS!$K$5:$K$504,"Efectivo")) | D13: =IF($A13="","",SUMIFS(VENTAS!$F$5:$F$504,VENTAS!$A$5:$A$504,$A13,VENTAS!$K$5:$K$504,"Transferencia")) | E13: =IF($A13="","",SUMIFS(VENTAS!$F$5:$F$504,VENTAS!$A$5:$A$504,$A13,VENTAS!$K$5:$K$504,"PayPhone")+SUMIFS(VENTAS!$F$5:$F$504,VENTAS!$A$5:$A$504,$A13,VENTAS!$K$5:$K$504,"Tarjeta")) | F13: =IF($A13="","",SUMIFS(GASTOS!$E$5:$E$304,GASTOS!$A$5:$A$304,$A13,GASTOS!$G$5:$G$304,"Efectivo",GASTOS!$H$5:$H$304,"SI")) | H13: =IF($A13="","",$B13+$C13-$F13-N($G13)) | J13: =IF($A13="","",IF($I13="","",$I13-$H13))
C14: =IF($A14="","",SUMIFS(VENTAS!$F$5:$F$504,VENTAS!$A$5:$A$504,$A14,VENTAS!$K$5:$K$504,"Efectivo")) | D14: =IF($A14="","",SUMIFS(VENTAS!$F$5:$F$504,VENTAS!$A$5:$A$504,$A14,VENTAS!$K$5:$K$504,"Transferencia")) | E14: =IF($A14="","",SUMIFS(VENTAS!$F$5:$F$504,VENTAS!$A$5:$A$504,$A14,VENTAS!$K$5:$K$504,"PayPhone")+SUMIFS(VENTAS!$F$5:$F$504,VENTAS!$A$5:$A$504,$A14,VENTAS!$K$5:$K$504,"Tarjeta")) | F14: =IF($A14="","",SUMIFS(GASTOS!$E$5:$E$304,GASTOS!$A$5:$A$304,$A14,GASTOS!$G$5:$G$304,"Efectivo",GASTOS!$H$5:$H$304,"SI")) | H14: =IF($A14="","",$B14+$C14-$F14-N($G14)) | J14: =IF($A14="","",IF($I14="","",$I14-$H14))
C15: =IF($A15="","",SUMIFS(VENTAS!$F$5:$F$504,VENTAS!$A$5:$A$504,$A15,VENTAS!$K$5:$K$504,"Efectivo")) | D15: =IF($A15="","",SUMIFS(VENTAS!$F$5:$F$504,VENTAS!$A$5:$A$504,$A15,VENTAS!$K$5:$K$504,"Transferencia")) | E15: =IF($A15="","",SUMIFS(VENTAS!$F$5:$F$504,VENTAS!$A$5:$A$504,$A15,VENTAS!$K$5:$K$504,"PayPhone")+SUMIFS(VENTAS!$F$5:$F$504,VENTAS!$A$5:$A$504,$A15,VENTAS!$K$5:$K$504,"Tarjeta")) | F15: =IF($A15="","",SUMIFS(GASTOS!$E$5:$E$304,GASTOS!$A$5:$A$304,$A15,GASTOS!$G$5:$G$304,"Efectivo",GASTOS!$H$5:$H$304,"SI")) | H15: =IF($A15="","",$B15+$C15-$F15-N($G15)) | J15: =IF($A15="","",IF($I15="","",$I15-$H15))
C16: =IF($A16="","",SUMIFS(VENTAS!$F$5:$F$504,VENTAS!$A$5:$A$504,$A16,VENTAS!$K$5:$K$504,"Efectivo")) | D16: =IF($A16="","",SUMIFS(VENTAS!$F$5:$F$504,VENTAS!$A$5:$A$504,$A16,VENTAS!$K$5:$K$504,"Transferencia")) | E16: =IF($A16="","",SUMIFS(VENTAS!$F$5:$F$504,VENTAS!$A$5:$A$504,$A16,VENTAS!$K$5:$K$504,"PayPhone")+SUMIFS(VENTAS!$F$5:$F$504,VENTAS!$A$5:$A$504,$A16,VENTAS!$K$5:$K$504,"Tarjeta")) | F16: =IF($A16="","",SUMIFS(GASTOS!$E$5:$E$304,GASTOS!$A$5:$A$304,$A16,GASTOS!$G$5:$G$304,"Efectivo",GASTOS!$H$5:$H$304,"SI")) | H16: =IF($A16="","",$B16+$C16-$F16-N($G16)) | J16: =IF($A16="","",IF($I16="","",$I16-$H16))
C17: =IF($A17="","",SUMIFS(VENTAS!$F$5:$F$504,VENTAS!$A$5:$A$504,$A17,VENTAS!$K$5:$K$504,"Efectivo")) | D17: =IF($A17="","",SUMIFS(VENTAS!$F$5:$F$504,VENTAS!$A$5:$A$504,$A17,VENTAS!$K$5:$K$504,"Transferencia")) | E17: =IF($A17="","",SUMIFS(VENTAS!$F$5:$F$504,VENTAS!$A$5:$A$504,$A17,VENTAS!$K$5:$K$504,"PayPhone")+SUMIFS(VENTAS!$F$5:$F$504,VENTAS!$A$5:$A$504,$A17,VENTAS!$K$5:$K$504,"Tarjeta")) | F17: =IF($A17="","",SUMIFS(GASTOS!$E$5:$E$304,GASTOS!$A$5:$A$304,$A17,GASTOS!$G$5:$G$304,"Efectivo",GASTOS!$H$5:$H$304,"SI")) | H17: =IF($A17="","",$B17+$C17-$F17-N($G17)) | J17: =IF($A17="","",IF($I17="","",$I17-$H17))
... C204: =IF($A204="","",SUMIFS(VENTAS!$F$5:$F$504,VENTAS!$A$5:$A$504,$A204,VENTAS!$K$5:$K$504,"Efectivo")) | D204: =IF($A204="","",SUMIFS(VENTAS!$F$5:$F$504,VENTAS!$A$5:$A$504,$A204,VENTAS!$K$5:$K$504,"Transferencia")) | E204: =IF($A204="","",SUMIFS(VENTAS!$F$5:$F$504,VENTAS!$A$5:$A$504,$A204,VENTAS!$K$5:$K$504,"PayPhone")+SUMIFS(VENTAS!$F$5:$F$504,VENTAS!$A$5:$A$504,$A204,VENTAS!$K$5:$K$504,"Tarjeta")) | F204: =IF($A204="","",SUMIFS(GASTOS!$E$5:$E$304,GASTOS!$A$5:$A$304,$A204,GASTOS!$G$5:$G$304,"Efectivo",GASTOS!$H$5:$H$304,"SI")) | H204: =IF($A204="","",$B204+$C204-$F204-N($G204)) | J204: =IF($A204="","",IF($I204="","",$I204-$H204))
B206: Descuadre negativo = falta plata. Positivo = sobra (mal cobrado o venta no registrada). Ambos son problema.

Sheet PRODUCTOS
A1: PRODUCTOS Y PRECIOS
A2: Precios de carta CON IVA incluido. El sistema descuenta el IVA para mostrarte tu utilidad REAL.
A4: ID | B4: Producto | C4: Categoria | D4: COSTO | E4: PVP c/IVA | F4: IVA % | G4: Ingreso neto (sin IVA) | H4: UTILIDAD | I4: MARGEN | J4: Margen objetivo | K4: PVP sugerido c/IVA | L4: ESTADO
A5: 1 | B5: Coco s/alcohol | C5: Granizado maquina | D5: =IF($B5="","",SUMIFS(RECETAS!$G$5:$G$254,RECETAS!$B$5:$B$254,$B5)+IFERROR(INDEX(COMBOS!$K$5:$K$24,MATCH($B5,COMBOS!$B$5:$B$24,0)),0)) | E5: 1.5 | F5: =IF($B5="","",INICIO!$C$5) | G5: =IFERROR(IF($B5="","",$E5/(1+$F5)),"") | H5: =IFERROR(IF($B5="","",$G5-$D5),"") | I5: =IFERROR(IF($B5="","",$H5/$G5),"") | J5: =IF($B5="","",INICIO!$C$9) | K5: =IFERROR(IF($B5="","",$D5/(1-$J5)*(1+$F5)),"") | L5: =IF($B5="","",IF($I5<0,"PIERDE PLATA",IF($I5<0.5,"MARGEN BAJO",IF($I5<0.65,"ACEPTABLE","EXCELENTE"))))
A6: 2 | B6: Frutos Rojos s/alcohol | C6: Granizado maquina | D6: =IF($B6="","",SUMIFS(RECETAS!$G$5:$G$254,RECETAS!$B$5:$B$254,$B6)+IFERROR(INDEX(COMBOS!$K$5:$K$24,MATCH($B6,COMBOS!$B$5:$B$24,0)),0)) | E6: 1.5 | F6: =IF($B6="","",INICIO!$C$5) | G6: =IFERROR(IF($B6="","",$E6/(1+$F6)),"") | H6: =IFERROR(IF($B6="","",$G6-$D6),"") | I6: =IFERROR(IF($B6="","",$H6/$G6),"") | J6: =IF($B6="","",INICIO!$C$9) | K6: =IFERROR(IF($B6="","",$D6/(1-$J6)*(1+$F6)),"") | L6: =IF($B6="","",IF($I6<0,"PIERDE PLATA",IF($I6<0.5,"MARGEN BAJO",IF($I6<0.65,"ACEPTABLE","EXCELENTE"))))
A7: 3 | B7: Maracuya s/alcohol | C7: Granizado maquina | D7: =IF($B7="","",SUMIFS(RECETAS!$G$5:$G$254,RECETAS!$B$5:$B$254,$B7)+IFERROR(INDEX(COMBOS!$K$5:$K$24,MATCH($B7,COMBOS!$B$5:$B$24,0)),0)) | E7: 1.5 | F7: =IF($B7="","",INICIO!$C$5) | G7: =IFERROR(IF($B7="","",$E7/(1+$F7)),"") | H7: =IFERROR(IF($B7="","",$G7-$D7),"") | I7: =IFERROR(IF($B7="","",$H7/$G7),"") | J7: =IF($B7="","",INICIO!$C$9) | K7: =IFERROR(IF($B7="","",$D7/(1-$J7)*(1+$F7)),"") | L7: =IF($B7="","",IF($I7<0,"PIERDE PLATA",IF($I7<0.5,"MARGEN BAJO",IF($I7<0.65,"ACEPTABLE","EXCELENTE"))))
A8: 4 | B8: Naranja s/alcohol | C8: Granizado maquina | D8: =IF($B8="","",SUMIFS(RECETAS!$G$5:$G$254,RECETAS!$B$5:$B$254,$B8)+IFERROR(INDEX(COMBOS!$K$5:$K$24,MATCH($B8,COMBOS!$B$5:$B$24,0)),0)) | E8: 1.5 | F8: =IF($B8="","",INICIO!$C$5) | G8: =IFERROR(IF($B8="","",$E8/(1+$F8)),"") | H8: =IFERROR(IF($B8="","",$G8-$D8),"") | I8: =IFERROR(IF($B8="","",$H8/$G8),"") | J8: =IF($B8="","",INICIO!$C$9) | K8: =IFERROR(IF($B8="","",$D8/(1-$J8)*(1+$F8)),"") | L8: =IF($B8="","",IF($I8<0,"PIERDE PLATA",IF($I8<0.5,"MARGEN BAJO",IF($I8<0.65,"ACEPTABLE","EXCELENTE"))))
A9: 5 | B9: Coco c/alcohol | C9: Granizado maquina | D9: =IF($B9="","",SUMIFS(RECETAS!$G$5:$G$254,RECETAS!$B$5:$B$254,$B9)+IFERROR(INDEX(COMBOS!$K$5:$K$24,MATCH($B9,COMBOS!$B$5:$B$24,0)),0)) | E9: 2 | F9: =IF($B9="","",INICIO!$C$5) | G9: =IFERROR(IF($B9="","",$E9/(1+$F9)),"") | H9: =IFERROR(IF($B9="","",$G9-$D9),"") | I9: =IFERROR(IF($B9="","",$H9/$G9),"") | J9: =IF($B9="","",INICIO!$C$9) | K9: =IFERROR(IF($B9="","",$D9/(1-$J9)*(1+$F9)),"") | L9: =IF($B9="","",IF($I9<0,"PIERDE PLATA",IF($I9<0.5,"MARGEN BAJO",IF($I9<0.65,"ACEPTABLE","EXCELENTE"))))
A10: 6 | B10: Frutos Rojos c/alcohol | C10: Granizado maquina | D10: =IF($B10="","",SUMIFS(RECETAS!$G$5:$G$254,RECETAS!$B$5:$B$254,$B10)+IFERROR(INDEX(COMBOS!$K$5:$K$24,MATCH($B10,COMBOS!$B$5:$B$24,0)),0)) | E10: 2 | F10: =IF($B10="","",INICIO!$C$5) | G10: =IFERROR(IF($B10="","",$E10/(1+$F10)),"") | H10: =IFERROR(IF($B10="","",$G10-$D10),"") | I10: =IFERROR(IF($B10="","",$H10/$G10),"") | J10: =IF($B10="","",INICIO!$C$9) | K10: =IFERROR(IF($B10="","",$D10/(1-$J10)*(1+$F10)),"") | L10: =IF($B10="","",IF($I10<0,"PIERDE PLATA",IF($I10<0.5,"MARGEN BAJO",IF($I10<0.65,"ACEPTABLE","EXCELENTE"))))
A11: 7 | B11: Maracuya c/alcohol | C11: Granizado maquina | D11: =IF($B11="","",SUMIFS(RECETAS!$G$5:$G$254,RECETAS!$B$5:$B$254,$B11)+IFERROR(INDEX(COMBOS!$K$5:$K$24,MATCH($B11,COMBOS!$B$5:$B$24,0)),0)) | E11: 2 | F11: =IF($B11="","",INICIO!$C$5) | G11: =IFERROR(IF($B11="","",$E11/(1+$F11)),"") | H11: =IFERROR(IF($B11="","",$G11-$D11),"") | I11: =IFERROR(IF($B11="","",$H11/$G11),"") | J11: =IF($B11="","",INICIO!$C$9) | K11: =IFERROR(IF($B11="","",$D11/(1-$J11)*(1+$F11)),"") | L11: =IF($B11="","",IF($I11<0,"PIERDE PLATA",IF($I11<0.5,"MARGEN BAJO",IF($I11<0.65,"ACEPTABLE","EXCELENTE"))))
A12: 8 | B12: Naranja c/alcohol | C12: Granizado maquina | D12: =IF($B12="","",SUMIFS(RECETAS!$G$5:$G$254,RECETAS!$B$5:$B$254,$B12)+IFERROR(INDEX(COMBOS!$K$5:$K$24,MATCH($B12,COMBOS!$B$5:$B$24,0)),0)) | E12: 2 | F12: =IF($B12="","",INICIO!$C$5) | G12: =IFERROR(IF($B12="","",$E12/(1+$F12)),"") | H12: =IFERROR(IF($B12="","",$G12-$D12),"") | I12: =IFERROR(IF($B12="","",$H12/$G12),"") | J12: =IF($B12="","",INICIO!$C$9) | K12: =IFERROR(IF($B12="","",$D12/(1-$J12)*(1+$F12)),"") | L12: =IF($B12="","",IF($I12<0,"PIERDE PLATA",IF($I12<0.5,"MARGEN BAJO",IF($I12<0.65,"ACEPTABLE","EXCELENTE"))))
A13: 9 | B13: Oreo s/alcohol | C13: Granizado especial | D13: =IF($B13="","",SUMIFS(RECETAS!$G$5:$G$254,RECETAS!$B$5:$B$254,$B13)+IFERROR(INDEX(COMBOS!$K$5:$K$24,MATCH($B13,COMBOS!$B$5:$B$24,0)),0)) | E13: 3 | F13: =IF($B13="","",INICIO!$C$5) | G13: =IFERROR(IF($B13="","",$E13/(1+$F13)),"") | H13: =IFERROR(IF($B13="","",$G13-$D13),"") | I13: =IFERROR(IF($B13="","",$H13/$G13),"") | J13: =IF($B13="","",INICIO!$C$9) | K13: =IFERROR(IF($B13="","",$D13/(1-$J13)*(1+$F13)),"") | L13: =IF($B13="","",IF($I13<0,"PIERDE PLATA",IF($I13<0.5,"MARGEN BAJO",IF($I13<0.65,"ACEPTABLE","EXCELENTE"))))
A14: 10 | B14: Nutella s/alcohol | C14: Granizado especial | D14: =IF($B14="","",SUMIFS(RECETAS!$G$5:$G$254,RECETAS!$B$5:$B$254,$B14)+IFERROR(INDEX(COMBOS!$K$5:$K$24,MATCH($B14,COMBOS!$B$5:$B$24,0)),0)) | E14: 3 | F14: =IF($B14="","",INICIO!$C$5) | G14: =IFERROR(IF($B14="","",$E14/(1+$F14)),"") | H14: =IFERROR(IF($B14="","",$G14-$D14),"") | I14: =IFERROR(IF($B14="","",$H14/$G14),"") | J14: =IF($B14="","",INICIO!$C$9) | K14: =IFERROR(IF($B14="","",$D14/(1-$J14)*(1+$F14)),"") | L14: =IF($B14="","",IF($I14<0,"PIERDE PLATA",IF($I14<0.5,"MARGEN BAJO",IF($I14<0.65,"ACEPTABLE","EXCELENTE"))))
A15: 11 | B15: Cafe s/alcohol | C15: Granizado especial | D15: =IF($B15="","",SUMIFS(RECETAS!$G$5:$G$254,RECETAS!$B$5:$B$254,$B15)+IFERROR(INDEX(COMBOS!$K$5:$K$24,MATCH($B15,COMBOS!$B$5:$B$24,0)),0)) | E15: 3 | F15: =IF($B15="","",INICIO!$C$5) | G15: =IFERROR(IF($B15="","",$E15/(1+$F15)),"") | H15: =IFERROR(IF($B15="","",$G15-$D15),"") | I15: =IFERROR(IF($B15="","",$H15/$G15),"") | J15: =IF($B15="","",INICIO!$C$9) | K15: =IFERROR(IF($B15="","",$D15/(1-$J15)*(1+$F15)),"") | L15: =IF($B15="","",IF($I15<0,"PIERDE PLATA",IF($I15<0.5,"MARGEN BAJO",IF($I15<0.65,"ACEPTABLE","EXCELENTE"))))
A16: 12 | B16: Oreo c/alcohol | C16: Granizado especial | D16: =IF($B16="","",SUMIFS(RECETAS!$G$5:$G$254,RECETAS!$B$5:$B$254,$B16)+IFERROR(INDEX(COMBOS!$K$5:$K$24,MATCH($B16,COMBOS!$B$5:$B$24,0)),0)) | E16: 3.5 | F16: =IF($B16="","",INICIO!$C$5) | G16: =IFERROR(IF($B16="","",$E16/(1+$F16)),"") | H16: =IFERROR(IF($B16="","",$G16-$D16),"") | I16: =IFERROR(IF($B16="","",$H16/$G16),"") | J16: =IF($B16="","",INICIO!$C$9) | K16: =IFERROR(IF($B16="","",$D16/(1-$J16)*(1+$F16)),"") | L16: =IF($B16="","",IF($I16<0,"PIERDE PLATA",IF($I16<0.5,"MARGEN BAJO",IF($I16<0.65,"ACEPTABLE","EXCELENTE"))))
... A24: 20 | B24: Combo Solo | C24: Combo | D24: =IF($B24="","",SUMIFS(RECETAS!$G$5:$G$254,RECETAS!$B$5:$B$254,$B24)+IFERROR(INDEX(COMBOS!$K$5:$K$24,MATCH($B24,COMBOS!$B$5:$B$24,0)),0)) | E24: 2.5 | F24: =IF($B24="","",INICIO!$C$5) | G24: =IFERROR(IF($B24="","",$E24/(1+$F24)),"") | H24: =IFERROR(IF($B24="","",$G24-$D24),"") | I24: =IFERROR(IF($B24="","",$H24/$G24),"") | J24: =IF($B24="","",INICIO!$C$9) | K24: =IFERROR(IF($B24="","",$D24/(1-$J24)*(1+$F24)),"") | L24: =IF($B24="","",IF($I24<0,"PIERDE PLATA",IF($I24<0.5,"MARGEN BAJO",IF($I24<0.65,"ACEPTABLE","EXCELENTE"))))
D25: =IF($B25="","",SUMIFS(RECETAS!$G$5:$G$254,RECETAS!$B$5:$B$254,$B25)+IFERROR(INDEX(COMBOS!$K$5:$K$24,MATCH($B25,COMBOS!$B$5:$B$24,0)),0)) | F25: =IF($B25="","",INICIO!$C$5) | G25: =IFERROR(IF($B25="","",$E25/(1+$F25)),"") | H25: =IFERROR(IF($B25="","",$G25-$D25),"") | I25: =IFERROR(IF($B25="","",$H25/$G25),"") | J25: =IF($B25="","",INICIO!$C$9) | K25: =IFERROR(IF($B25="","",$D25/(1-$J25)*(1+$F25)),"") | L25: =IF($B25="","",IF($I25<0,"PIERDE PLATA",IF($I25<0.5,"MARGEN BAJO",IF($I25<0.65,"ACEPTABLE","EXCELENTE"))))
D26: =IF($B26="","",SUMIFS(RECETAS!$G$5:$G$254,RECETAS!$B$5:$B$254,$B26)+IFERROR(INDEX(COMBOS!$K$5:$K$24,MATCH($B26,COMBOS!$B$5:$B$24,0)),0)) | F26: =IF($B26="","",INICIO!$C$5) | G26: =IFERROR(IF($B26="","",$E26/(1+$F26)),"") | H26: =IFERROR(IF($B26="","",$G26-$D26),"") | I26: =IFERROR(IF($B26="","",$H26/$G26),"") | J26: =IF($B26="","",INICIO!$C$9) | K26: =IFERROR(IF($B26="","",$D26/(1-$J26)*(1+$F26)),"") | L26: =IF($B26="","",IF($I26<0,"PIERDE PLATA",IF($I26<0.5,"MARGEN BAJO",IF($I26<0.65,"ACEPTABLE","EXCELENTE"))))
D27: =IF($B27="","",SUMIFS(RECETAS!$G$5:$G$254,RECETAS!$B$5:$B$254,$B27)+IFERROR(INDEX(COMBOS!$K$5:$K$24,MATCH($B27,COMBOS!$B$5:$B$24,0)),0)) | F27: =IF($B27="","",INICIO!$C$5) | G27: =IFERROR(IF($B27="","",$E27/(1+$F27)),"") | H27: =IFERROR(IF($B27="","",$G27-$D27),"") | I27: =IFERROR(IF($B27="","",$H27/$G27),"") | J27: =IF($B27="","",INICIO!$C$9) | K27: =IFERROR(IF($B27="","",$D27/(1-$J27)*(1+$F27)),"") | L27: =IF($B27="","",IF($I27<0,"PIERDE PLATA",IF($I27<0.5,"MARGEN BAJO",IF($I27<0.65,"ACEPTABLE","EXCELENTE"))))
D28: =IF($B28="","",SUMIFS(RECETAS!$G$5:$G$254,RECETAS!$B$5:$B$254,$B28)+IFERROR(INDEX(COMBOS!$K$5:$K$24,MATCH($B28,COMBOS!$B$5:$B$24,0)),0)) | F28: =IF($B28="","",INICIO!$C$5) | G28: =IFERROR(IF($B28="","",$E28/(1+$F28)),"") | H28: =IFERROR(IF($B28="","",$G28-$D28),"") | I28: =IFERROR(IF($B28="","",$H28/$G28),"") | J28: =IF($B28="","",INICIO!$C$9) | K28: =IFERROR(IF($B28="","",$D28/(1-$J28)*(1+$F28)),"") | L28: =IF($B28="","",IF($I28<0,"PIERDE PLATA",IF($I28<0.5,"MARGEN BAJO",IF($I28<0.65,"ACEPTABLE","EXCELENTE"))))
D29: =IF($B29="","",SUMIFS(RECETAS!$G$5:$G$254,RECETAS!$B$5:$B$254,$B29)+IFERROR(INDEX(COMBOS!$K$5:$K$24,MATCH($B29,COMBOS!$B$5:$B$24,0)),0)) | F29: =IF($B29="","",INICIO!$C$5) | G29: =IFERROR(IF($B29="","",$E29/(1+$F29)),"") | H29: =IFERROR(IF($B29="","",$G29-$D29),"") | I29: =IFERROR(IF($B29="","",$H29/$G29),"") | J29: =IF($B29="","",INICIO!$C$9) | K29: =IFERROR(IF($B29="","",$D29/(1-$J29)*(1+$F29)),"") | L29: =IF($B29="","",IF($I29<0,"PIERDE PLATA",IF($I29<0.5,"MARGEN BAJO",IF($I29<0.65,"ACEPTABLE","EXCELENTE"))))
D30: =IF($B30="","",SUMIFS(RECETAS!$G$5:$G$254,RECETAS!$B$5:$B$254,$B30)+IFERROR(INDEX(COMBOS!$K$5:$K$24,MATCH($B30,COMBOS!$B$5:$B$24,0)),0)) | F30: =IF($B30="","",INICIO!$C$5) | G30: =IFERROR(IF($B30="","",$E30/(1+$F30)),"") | H30: =IFERROR(IF($B30="","",$G30-$D30),"") | I30: =IFERROR(IF($B30="","",$H30/$G30),"") | J30: =IF($B30="","",INICIO!$C$9) | K30: =IFERROR(IF($B30="","",$D30/(1-$J30)*(1+$F30)),"") | L30: =IF($B30="","",IF($I30<0,"PIERDE PLATA",IF($I30<0.5,"MARGEN BAJO",IF($I30<0.65,"ACEPTABLE","EXCELENTE"))))
D31: =IF($B31="","",SUMIFS(RECETAS!$G$5:$G$254,RECETAS!$B$5:$B$254,$B31)+IFERROR(INDEX(COMBOS!$K$5:$K$24,MATCH($B31,COMBOS!$B$5:$B$24,0)),0)) | F31: =IF($B31="","",INICIO!$C$5) | G31: =IFERROR(IF($B31="","",$E31/(1+$F31)),"") | H31: =IFERROR(IF($B31="","",$G31-$D31),"") | I31: =IFERROR(IF($B31="","",$H31/$G31),"") | J31: =IF($B31="","",INICIO!$C$9) | K31: =IFERROR(IF($B31="","",$D31/(1-$J31)*(1+$F31)),"") | L31: =IF($B31="","",IF($I31<0,"PIERDE PLATA",IF($I31<0.5,"MARGEN BAJO",IF($I31<0.65,"ACEPTABLE","EXCELENTE"))))
D32: =IF($B32="","",SUMIFS(RECETAS!$G$5:$G$254,RECETAS!$B$5:$B$254,$B32)+IFERROR(INDEX(COMBOS!$K$5:$K$24,MATCH($B32,COMBOS!$B$5:$B$24,0)),0)) | F32: =IF($B32="","",INICIO!$C$5) | G32: =IFERROR(IF($B32="","",$E32/(1+$F32)),"") | H32: =IFERROR(IF($B32="","",$G32-$D32),"") | I32: =IFERROR(IF($B32="","",$H32/$G32),"") | J32: =IF($B32="","",INICIO!$C$9) | K32: =IFERROR(IF($B32="","",$D32/(1-$J32)*(1+$F32)),"") | L32: =IF($B32="","",IF($I32<0,"PIERDE PLATA",IF($I32<0.5,"MARGEN BAJO",IF($I32<0.65,"ACEPTABLE","EXCELENTE"))))
D33: =IF($B33="","",SUMIFS(RECETAS!$G$5:$G$254,RECETAS!$B$5:$B$254,$B33)+IFERROR(INDEX(COMBOS!$K$5:$K$24,MATCH($B33,COMBOS!$B$5:$B$24,0)),0)) | F33: =IF($B33="","",INICIO!$C$5) | G33: =IFERROR(IF($B33="","",$E33/(1+$F33)),"") | H33: =IFERROR(IF($B33="","",$G33-$D33),"") | I33: =IFERROR(IF($B33="","",$H33/$G33),"") | J33: =IF($B33="","",INICIO!$C$9) | K33: =IFERROR(IF($B33="","",$D33/(1-$J33)*(1+$F33)),"") | L33: =IF($B33="","",IF($I33<0,"PIERDE PLATA",IF($I33<0.5,"MARGEN BAJO",IF($I33<0.65,"ACEPTABLE","EXCELENTE"))))
D34: =IF($B34="","",SUMIFS(RECETAS!$G$5:$G$254,RECETAS!$B$5:$B$254,$B34)+IFERROR(INDEX(COMBOS!$K$5:$K$24,MATCH($B34,COMBOS!$B$5:$B$24,0)),0)) | F34: =IF($B34="","",INICIO!$C$5) | G34: =IFERROR(IF($B34="","",$E34/(1+$F34)),"") | H34: =IFERROR(IF($B34="","",$G34-$D34),"") | I34: =IFERROR(IF($B34="","",$H34/$G34),"") | J34: =IF($B34="","",INICIO!$C$9) | K34: =IFERROR(IF($B34="","",$D34/(1-$J34)*(1+$F34)),"") | L34: =IF($B34="","",IF($I34<0,"PIERDE PLATA",IF($I34<0.5,"MARGEN BAJO",IF($I34<0.65,"ACEPTABLE","EXCELENTE"))))
D35: =IF($B35="","",SUMIFS(RECETAS!$G$5:$G$254,RECETAS!$B$5:$B$254,$B35)+IFERROR(INDEX(COMBOS!$K$5:$K$24,MATCH($B35,COMBOS!$B$5:$B$24,0)),0)) | F35: =IF($B35="","",INICIO!$C$5) | G35: =IFERROR(IF($B35="","",$E35/(1+$F35)),"") | H35: =IFERROR(IF($B35="","",$G35-$D35),"") | I35: =IFERROR(IF($B35="","",$H35/$G35),"") | J35: =IF($B35="","",INICIO!$C$9) | K35: =IFERROR(IF($B35="","",$D35/(1-$J35)*(1+$F35)),"") | L35: =IF($B35="","",IF($I35<0,"PIERDE PLATA",IF($I35<0.5,"MARGEN BAJO",IF($I35<0.65,"ACEPTABLE","EXCELENTE"))))
D36: =IF($B36="","",SUMIFS(RECETAS!$G$5:$G$254,RECETAS!$B$5:$B$254,$B36)+IFERROR(INDEX(COMBOS!$K$5:$K$24,MATCH($B36,COMBOS!$B$5:$B$24,0)),0)) | F36: =IF($B36="","",INICIO!$C$5) | G36: =IFERROR(IF($B36="","",$E36/(1+$F36)),"") | H36: =IFERROR(IF($B36="","",$G36-$D36),"") | I36: =IFERROR(IF($B36="","",$H36/$G36),"") | J36: =IF($B36="","",INICIO!$C$9) | K36: =IFERROR(IF($B36="","",$D36/(1-$J36)*(1+$F36)),"") | L36: =IF($B36="","",IF($I36<0,"PIERDE PLATA",IF($I36<0.5,"MARGEN BAJO",IF($I36<0.65,"ACEPTABLE","EXCELENTE"))))
... D44: =IF($B44="","",SUMIFS(RECETAS!$G$5:$G$254,RECETAS!$B$5:$B$254,$B44)+IFERROR(INDEX(COMBOS!$K$5:$K$24,MATCH($B44,COMBOS!$B$5:$B$24,0)),0)) | F44: =IF($B44="","",INICIO!$C$5) | G44: =IFERROR(IF($B44="","",$E44/(1+$F44)),"") | H44: =IFERROR(IF($B44="","",$G44-$D44),"") | I44: =IFERROR(IF($B44="","",$H44/$G44),"") | J44: =IF($B44="","",INICIO!$C$9) | K44: =IFERROR(IF($B44="","",$D44/(1-$J44)*(1+$F44)),"") | L44: =IF($B44="","",IF($I44<0,"PIERDE PLATA",IF($I44<0.5,"MARGEN BAJO",IF($I44<0.65,"ACEPTABLE","EXCELENTE"))))
B46: OJO: con IVA 15%, un granizado de $1.50 te deja $1.30 de ingreso real. El PVP sugerido ya viene con IVA para que lo pongas tal cual en la carta.

Sheet COMBOS
A1: COMBOS
A2: Arma el combo, mira cuanto margen sacrificas ANTES de lanzarlo. Los combos aparecen tambien en PRODUCTOS para poder venderlos.
A4: ID | B4: Nombre del combo | C4: Item 1 | D4: Cant 1 | E4: Item 2 | F4: Cant 2 | G4: Item 3 | H4: Cant 3 | I4: Precio suelto (c/IVA) | J4: PVP combo (c/IVA) | K4: COSTO COMBO | L4: Descuento que das | M4: Margen combo
A5: 1 | B5: Combo Pareja | C5: Coco c/alcohol | D5: 2 | E5: Papas en cono natural | F5: 1 | I5: =IF($B5="","",IFERROR(INDEX(PRODUCTOS!$E$5:$E$44,MATCH($C5,PRODUCTOS!$B$5:$B$44,0))*N($D5),0)+IFERROR(INDEX(PRODUCTOS!$E$5:$E$44,MATCH($E5,PRODUCTOS!$B$5:$B$44,0))*N($F5),0)+IFERROR(INDEX(PRODUCTOS!$E$5:$E$44,MATCH($G5,PRODUCTOS!$B$5:$B$44,0))*N($H5),0)) | J5: 5 | K5: =IF($B5="","",IFERROR(SUMIFS(RECETAS!$G$5:$G$254,RECETAS!$B$5:$B$254,$C5)*N($D5),0)+IFERROR(SUMIFS(RECETAS!$G$5:$G$254,RECETAS!$B$5:$B$254,$E5)*N($F5),0)+IFERROR(SUMIFS(RECETAS!$G$5:$G$254,RECETAS!$B$5:$B$254,$G5)*N($H5),0)) | L5: =IFERROR(IF($B5="","",($I5-$J5)/$I5),"") | M5: =IFERROR(IF($B5="","",($J5/(1+INICIO!$C$5)-$K5)/($J5/(1+INICIO!$C$5))),"")
A6: 2 | B6: Combo Amigos (4 granizados) | C6: Coco s/alcohol | D6: 4 | I6: =IF($B6="","",IFERROR(INDEX(PRODUCTOS!$E$5:$E$44,MATCH($C6,PRODUCTOS!$B$5:$B$44,0))*N($D6),0)+IFERROR(INDEX(PRODUCTOS!$E$5:$E$44,MATCH($E6,PRODUCTOS!$B$5:$B$44,0))*N($F6),0)+IFERROR(INDEX(PRODUCTOS!$E$5:$E$44,MATCH($G6,PRODUCTOS!$B$5:$B$44,0))*N($H6),0)) | J6: 5 | K6: =IF($B6="","",IFERROR(SUMIFS(RECETAS!$G$5:$G$254,RECETAS!$B$5:$B$254,$C6)*N($D6),0)+IFERROR(SUMIFS(RECETAS!$G$5:$G$254,RECETAS!$B$5:$B$254,$E6)*N($F6),0)+IFERROR(SUMIFS(RECETAS!$G$5:$G$254,RECETAS!$B$5:$B$254,$G6)*N($H6),0)) | L6: =IFERROR(IF($B6="","",($I6-$J6)/$I6),"") | M6: =IFERROR(IF($B6="","",($J6/(1+INICIO!$C$5)-$K6)/($J6/(1+INICIO!$C$5))),"")
A7: 3 | B7: Combo Premium | C7: Oreo s/alcohol | D7: 2 | E7: Papas en cono + salsa | F7: 1 | I7: =IF($B7="","",IFERROR(INDEX(PRODUCTOS!$E$5:$E$44,MATCH($C7,PRODUCTOS!$B$5:$B$44,0))*N($D7),0)+IFERROR(INDEX(PRODUCTOS!$E$5:$E$44,MATCH($E7,PRODUCTOS!$B$5:$B$44,0))*N($F7),0)+IFERROR(INDEX(PRODUCTOS!$E$5:$E$44,MATCH($G7,PRODUCTOS!$B$5:$B$44,0))*N($H7),0)) | J7: 7.5 | K7: =IF($B7="","",IFERROR(SUMIFS(RECETAS!$G$5:$G$254,RECETAS!$B$5:$B$254,$C7)*N($D7),0)+IFERROR(SUMIFS(RECETAS!$G$5:$G$254,RECETAS!$B$5:$B$254,$E7)*N($F7),0)+IFERROR(SUMIFS(RECETAS!$G$5:$G$254,RECETAS!$B$5:$B$254,$G7)*N($H7),0)) | L7: =IFERROR(IF($B7="","",($I7-$J7)/$I7),"") | M7: =IFERROR(IF($B7="","",($J7/(1+INICIO!$C$5)-$K7)/($J7/(1+INICIO!$C$5))),"")
A8: 4 | B8: Combo Solo | C8: Maracuya s/alcohol | D8: 1 | E8: Papas en cono natural | F8: 1 | I8: =IF($B8="","",IFERROR(INDEX(PRODUCTOS!$E$5:$E$44,MATCH($C8,PRODUCTOS!$B$5:$B$44,0))*N($D8),0)+IFERROR(INDEX(PRODUCTOS!$E$5:$E$44,MATCH($E8,PRODUCTOS!$B$5:$B$44,0))*N($F8),0)+IFERROR(INDEX(PRODUCTOS!$E$5:$E$44,MATCH($G8,PRODUCTOS!$B$5:$B$44,0))*N($H8),0)) | J8: 2.5 | K8: =IF($B8="","",IFERROR(SUMIFS(RECETAS!$G$5:$G$254,RECETAS!$B$5:$B$254,$C8)*N($D8),0)+IFERROR(SUMIFS(RECETAS!$G$5:$G$254,RECETAS!$B$5:$B$254,$E8)*N($F8),0)+IFERROR(SUMIFS(RECETAS!$G$5:$G$254,RECETAS!$B$5:$B$254,$G8)*N($H8),0)) | L8: =IFERROR(IF($B8="","",($I8-$J8)/$I8),"") | M8: =IFERROR(IF($B8="","",($J8/(1+INICIO!$C$5)-$K8)/($J8/(1+INICIO!$C$5))),"")
I9: =IF($B9="","",IFERROR(INDEX(PRODUCTOS!$E$5:$E$44,MATCH($C9,PRODUCTOS!$B$5:$B$44,0))*N($D9),0)+IFERROR(INDEX(PRODUCTOS!$E$5:$E$44,MATCH($E9,PRODUCTOS!$B$5:$B$44,0))*N($F9),0)+IFERROR(INDEX(PRODUCTOS!$E$5:$E$44,MATCH($G9,PRODUCTOS!$B$5:$B$44,0))*N($H9),0)) | K9: =IF($B9="","",IFERROR(SUMIFS(RECETAS!$G$5:$G$254,RECETAS!$B$5:$B$254,$C9)*N($D9),0)+IFERROR(SUMIFS(RECETAS!$G$5:$G$254,RECETAS!$B$5:$B$254,$E9)*N($F9),0)+IFERROR(SUMIFS(RECETAS!$G$5:$G$254,RECETAS!$B$5:$B$254,$G9)*N($H9),0)) | L9: =IFERROR(IF($B9="","",($I9-$J9)/$I9),"") | M9: =IFERROR(IF($B9="","",($J9/(1+INICIO!$C$5)-$K9)/($J9/(1+INICIO!$C$5))),"")
I10: =IF($B10="","",IFERROR(INDEX(PRODUCTOS!$E$5:$E$44,MATCH($C10,PRODUCTOS!$B$5:$B$44,0))*N($D10),0)+IFERROR(INDEX(PRODUCTOS!$E$5:$E$44,MATCH($E10,PRODUCTOS!$B$5:$B$44,0))*N($F10),0)+IFERROR(INDEX(PRODUCTOS!$E$5:$E$44,MATCH($G10,PRODUCTOS!$B$5:$B$44,0))*N($H10),0)) | K10: =IF($B10="","",IFERROR(SUMIFS(RECETAS!$G$5:$G$254,RECETAS!$B$5:$B$254,$C10)*N($D10),0)+IFERROR(SUMIFS(RECETAS!$G$5:$G$254,RECETAS!$B$5:$B$254,$E10)*N($F10),0)+IFERROR(SUMIFS(RECETAS!$G$5:$G$254,RECETAS!$B$5:$B$254,$G10)*N($H10),0)) | L10: =IFERROR(IF($B10="","",($I10-$J10)/$I10),"") | M10: =IFERROR(IF($B10="","",($J10/(1+INICIO!$C$5)-$K10)/($J10/(1+INICIO!$C$5))),"")
I11: =IF($B11="","",IFERROR(INDEX(PRODUCTOS!$E$5:$E$44,MATCH($C11,PRODUCTOS!$B$5:$B$44,0))*N($D11),0)+IFERROR(INDEX(PRODUCTOS!$E$5:$E$44,MATCH($E11,PRODUCTOS!$B$5:$B$44,0))*N($F11),0)+IFERROR(INDEX(PRODUCTOS!$E$5:$E$44,MATCH($G11,PRODUCTOS!$B$5:$B$44,0))*N($H11),0)) | K11: =IF($B11="","",IFERROR(SUMIFS(RECETAS!$G$5:$G$254,RECETAS!$B$5:$B$254,$C11)*N($D11),0)+IFERROR(SUMIFS(RECETAS!$G$5:$G$254,RECETAS!$B$5:$B$254,$E11)*N($F11),0)+IFERROR(SUMIFS(RECETAS!$G$5:$G$254,RECETAS!$B$5:$B$254,$G11)*N($H11),0)) | L11: =IFERROR(IF($B11="","",($I11-$J11)/$I11),"") | M11: =IFERROR(IF($B11="","",($J11/(1+INICIO!$C$5)-$K11)/($J11/(1+INICIO!$C$5))),"")
I12: =IF($B12="","",IFERROR(INDEX(PRODUCTOS!$E$5:$E$44,MATCH($C12,PRODUCTOS!$B$5:$B$44,0))*N($D12),0)+IFERROR(INDEX(PRODUCTOS!$E$5:$E$44,MATCH($E12,PRODUCTOS!$B$5:$B$44,0))*N($F12),0)+IFERROR(INDEX(PRODUCTOS!$E$5:$E$44,MATCH($G12,PRODUCTOS!$B$5:$B$44,0))*N($H12),0)) | K12: =IF($B12="","",IFERROR(SUMIFS(RECETAS!$G$5:$G$254,RECETAS!$B$5:$B$254,$C12)*N($D12),0)+IFERROR(SUMIFS(RECETAS!$G$5:$G$254,RECETAS!$B$5:$B$254,$E12)*N($F12),0)+IFERROR(SUMIFS(RECETAS!$G$5:$G$254,RECETAS!$B$5:$B$254,$G12)*N($H12),0)) | L12: =IFERROR(IF($B12="","",($I12-$J12)/$I12),"") | M12: =IFERROR(IF($B12="","",($J12/(1+INICIO!$C$5)-$K12)/($J12/(1+INICIO!$C$5))),"")
I13: =IF($B13="","",IFERROR(INDEX(PRODUCTOS!$E$5:$E$44,MATCH($C13,PRODUCTOS!$B$5:$B$44,0))*N($D13),0)+IFERROR(INDEX(PRODUCTOS!$E$5:$E$44,MATCH($E13,PRODUCTOS!$B$5:$B$44,0))*N($F13),0)+IFERROR(INDEX(PRODUCTOS!$E$5:$E$44,MATCH($G13,PRODUCTOS!$B$5:$B$44,0))*N($H13),0)) | K13: =IF($B13="","",IFERROR(SUMIFS(RECETAS!$G$5:$G$254,RECETAS!$B$5:$B$254,$C13)*N($D13),0)+IFERROR(SUMIFS(RECETAS!$G$5:$G$254,RECETAS!$B$5:$B$254,$E13)*N($F13),0)+IFERROR(SUMIFS(RECETAS!$G$5:$G$254,RECETAS!$B$5:$B$254,$G13)*N($H13),0)) | L13: =IFERROR(IF($B13="","",($I13-$J13)/$I13),"") | M13: =IFERROR(IF($B13="","",($J13/(1+INICIO!$C$5)-$K13)/($J13/(1+INICIO!$C$5))),"")
I14: =IF($B14="","",IFERROR(INDEX(PRODUCTOS!$E$5:$E$44,MATCH($C14,PRODUCTOS!$B$5:$B$44,0))*N($D14),0)+IFERROR(INDEX(PRODUCTOS!$E$5:$E$44,MATCH($E14,PRODUCTOS!$B$5:$B$44,0))*N($F14),0)+IFERROR(INDEX(PRODUCTOS!$E$5:$E$44,MATCH($G14,PRODUCTOS!$B$5:$B$44,0))*N($H14),0)) | K14: =IF($B14="","",IFERROR(SUMIFS(RECETAS!$G$5:$G$254,RECETAS!$B$5:$B$254,$C14)*N($D14),0)+IFERROR(SUMIFS(RECETAS!$G$5:$G$254,RECETAS!$B$5:$B$254,$E14)*N($F14),0)+IFERROR(SUMIFS(RECETAS!$G$5:$G$254,RECETAS!$B$5:$B$254,$G14)*N($H14),0)) | L14: =IFERROR(IF($B14="","",($I14-$J14)/$I14),"") | M14: =IFERROR(IF($B14="","",($J14/(1+INICIO!$C$5)-$K14)/($J14/(1+INICIO!$C$5))),"")
I15: =IF($B15="","",IFERROR(INDEX(PRODUCTOS!$E$5:$E$44,MATCH($C15,PRODUCTOS!$B$5:$B$44,0))*N($D15),0)+IFERROR(INDEX(PRODUCTOS!$E$5:$E$44,MATCH($E15,PRODUCTOS!$B$5:$B$44,0))*N($F15),0)+IFERROR(INDEX(PRODUCTOS!$E$5:$E$44,MATCH($G15,PRODUCTOS!$B$5:$B$44,0))*N($H15),0)) | K15: =IF($B15="","",IFERROR(SUMIFS(RECETAS!$G$5:$G$254,RECETAS!$B$5:$B$254,$C15)*N($D15),0)+IFERROR(SUMIFS(RECETAS!$G$5:$G$254,RECETAS!$B$5:$B$254,$E15)*N($F15),0)+IFERROR(SUMIFS(RECETAS!$G$5:$G$254,RECETAS!$B$5:$B$254,$G15)*N($H15),0)) | L15: =IFERROR(IF($B15="","",($I15-$J15)/$I15),"") | M15: =IFERROR(IF($B15="","",($J15/(1+INICIO!$C$5)-$K15)/($J15/(1+INICIO!$C$5))),"")
I16: =IF($B16="","",IFERROR(INDEX(PRODUCTOS!$E$5:$E$44,MATCH($C16,PRODUCTOS!$B$5:$B$44,0))*N($D16),0)+IFERROR(INDEX(PRODUCTOS!$E$5:$E$44,MATCH($E16,PRODUCTOS!$B$5:$B$44,0))*N($F16),0)+IFERROR(INDEX(PRODUCTOS!$E$5:$E$44,MATCH($G16,PRODUCTOS!$B$5:$B$44,0))*N($H16),0)) | K16: =IF($B16="","",IFERROR(SUMIFS(RECETAS!$G$5:$G$254,RECETAS!$B$5:$B$254,$C16)*N($D16),0)+IFERROR(SUMIFS(RECETAS!$G$5:$G$254,RECETAS!$B$5:$B$254,$E16)*N($F16),0)+IFERROR(SUMIFS(RECETAS!$G$5:$G$254,RECETAS!$B$5:$B$254,$G16)*N($H16),0)) | L16: =IFERROR(IF($B16="","",($I16-$J16)/$I16),"") | M16: =IFERROR(IF($B16="","",($J16/(1+INICIO!$C$5)-$K16)/($J16/(1+INICIO!$C$5))),"")
I17: =IF($B17="","",IFERROR(INDEX(PRODUCTOS!$E$5:$E$44,MATCH($C17,PRODUCTOS!$B$5:$B$44,0))*N($D17),0)+IFERROR(INDEX(PRODUCTOS!$E$5:$E$44,MATCH($E17,PRODUCTOS!$B$5:$B$44,0))*N($F17),0)+IFERROR(INDEX(PRODUCTOS!$E$5:$E$44,MATCH($G17,PRODUCTOS!$B$5:$B$44,0))*N($H17),0)) | K17: =IF($B17="","",IFERROR(SUMIFS(RECETAS!$G$5:$G$254,RECETAS!$B$5:$B$254,$C17)*N($D17),0)+IFERROR(SUMIFS(RECETAS!$G$5:$G$254,RECETAS!$B$5:$B$254,$E17)*N($F17),0)+IFERROR(SUMIFS(RECETAS!$G$5:$G$254,RECETAS!$B$5:$B$254,$G17)*N($H17),0)) | L17: =IFERROR(IF($B17="","",($I17-$J17)/$I17),"") | M17: =IFERROR(IF($B17="","",($J17/(1+INICIO!$C$5)-$K17)/($J17/(1+INICIO!$C$5))),"")
I18: =IF($B18="","",IFERROR(INDEX(PRODUCTOS!$E$5:$E$44,MATCH($C18,PRODUCTOS!$B$5:$B$44,0))*N($D18),0)+IFERROR(INDEX(PRODUCTOS!$E$5:$E$44,MATCH($E18,PRODUCTOS!$B$5:$B$44,0))*N($F18),0)+IFERROR(INDEX(PRODUCTOS!$E$5:$E$44,MATCH($G18,PRODUCTOS!$B$5:$B$44,0))*N($H18),0)) | K18: =IF($B18="","",IFERROR(SUMIFS(RECETAS!$G$5:$G$254,RECETAS!$B$5:$B$254,$C18)*N($D18),0)+IFERROR(SUMIFS(RECETAS!$G$5:$G$254,RECETAS!$B$5:$B$254,$E18)*N($F18),0)+IFERROR(SUMIFS(RECETAS!$G$5:$G$254,RECETAS!$B$5:$B$254,$G18)*N($H18),0)) | L18: =IFERROR(IF($B18="","",($I18-$J18)/$I18),"") | M18: =IFERROR(IF($B18="","",($J18/(1+INICIO!$C$5)-$K18)/($J18/(1+INICIO!$C$5))),"")
I19: =IF($B19="","",IFERROR(INDEX(PRODUCTOS!$E$5:$E$44,MATCH($C19,PRODUCTOS!$B$5:$B$44,0))*N($D19),0)+IFERROR(INDEX(PRODUCTOS!$E$5:$E$44,MATCH($E19,PRODUCTOS!$B$5:$B$44,0))*N($F19),0)+IFERROR(INDEX(PRODUCTOS!$E$5:$E$44,MATCH($G19,PRODUCTOS!$B$5:$B$44,0))*N($H19),0)) | K19: =IF($B19="","",IFERROR(SUMIFS(RECETAS!$G$5:$G$254,RECETAS!$B$5:$B$254,$C19)*N($D19),0)+IFERROR(SUMIFS(RECETAS!$G$5:$G$254,RECETAS!$B$5:$B$254,$E19)*N($F19),0)+IFERROR(SUMIFS(RECETAS!$G$5:$G$254,RECETAS!$B$5:$B$254,$G19)*N($H19),0)) | L19: =IFERROR(IF($B19="","",($I19-$J19)/$I19),"") | M19: =IFERROR(IF($B19="","",($J19/(1+INICIO!$C$5)-$K19)/($J19/(1+INICIO!$C$5))),"")
I20: =IF($B20="","",IFERROR(INDEX(PRODUCTOS!$E$5:$E$44,MATCH($C20,PRODUCTOS!$B$5:$B$44,0))*N($D20),0)+IFERROR(INDEX(PRODUCTOS!$E$5:$E$44,MATCH($E20,PRODUCTOS!$B$5:$B$44,0))*N($F20),0)+IFERROR(INDEX(PRODUCTOS!$E$5:$E$44,MATCH($G20,PRODUCTOS!$B$5:$B$44,0))*N($H20),0)) | K20: =IF($B20="","",IFERROR(SUMIFS(RECETAS!$G$5:$G$254,RECETAS!$B$5:$B$254,$C20)*N($D20),0)+IFERROR(SUMIFS(RECETAS!$G$5:$G$254,RECETAS!$B$5:$B$254,$E20)*N($F20),0)+IFERROR(SUMIFS(RECETAS!$G$5:$G$254,RECETAS!$B$5:$B$254,$G20)*N($H20),0)) | L20: =IFERROR(IF($B20="","",($I20-$J20)/$I20),"") | M20: =IFERROR(IF($B20="","",($J20/(1+INICIO!$C$5)-$K20)/($J20/(1+INICIO!$C$5))),"")
... I24: =IF($B24="","",IFERROR(INDEX(PRODUCTOS!$E$5:$E$44,MATCH($C24,PRODUCTOS!$B$5:$B$44,0))*N($D24),0)+IFERROR(INDEX(PRODUCTOS!$E$5:$E$44,MATCH($E24,PRODUCTOS!$B$5:$B$44,0))*N($F24),0)+IFERROR(INDEX(PRODUCTOS!$E$5:$E$44,MATCH($G24,PRODUCTOS!$B$5:$B$44,0))*N($H24),0)) | K24: =IF($B24="","",IFERROR(SUMIFS(RECETAS!$G$5:$G$254,RECETAS!$B$5:$B$254,$C24)*N($D24),0)+IFERROR(SUMIFS(RECETAS!$G$5:$G$254,RECETAS!$B$5:$B$254,$E24)*N($F24),0)+IFERROR(SUMIFS(RECETAS!$G$5:$G$254,RECETAS!$B$5:$B$254,$G24)*N($H24),0)) | L24: =IFERROR(IF($B24="","",($I24-$J24)/$I24),"") | M24: =IFERROR(IF($B24="","",($J24/(1+INICIO!$C$5)-$K24)/($J24/(1+INICIO!$C$5))),"")
B27: Regla: si el margen del combo baja de 55%, no lo lances. Estas regalando plata para vender lo mismo.

Sheet RECETAS
A1: RECETAS
A2: Una fila por cada ingrediente de cada producto. El costo se jala solo desde INSUMOS.
A4: # | B4: Producto | C4: Insumo | D4: Cantidad | E4: Unidad | F4: Costo unitario | G4: COSTO LINEA | H4: Notas de preparacion | I4: Uds. vendidas del producto (mes DASHBOARD) | J4: Consumo del insumo en el mes
A5: 1 | B5: Coco s/alcohol | C5: Jarabe Coco | D5: 63 | E5: =IFERROR(IF($C5="","",INDEX(INSUMOS!$G$5:$G$84,MATCH($C5,INSUMOS!$B$5:$B$84,0))),"") | F5: =IFERROR(IF($C5="","",INDEX(INSUMOS!$I$5:$I$84,MATCH($C5,INSUMOS!$B$5:$B$84,0))),"") | G5: =IFERROR(IF($C5="","",$D5*$F5),"") | H5: 63ml jarabe + 190ml agua | I5: =IF($B5="","",SUMIFS(VENTAS!$D$5:$D$504,VENTAS!$B$5:$B$504,INICIO!$C$8,VENTAS!$C$5:$C$504,$B5)) | J5: =IF($C5="","",$D5*$I5)
A6: 2 | B6: Coco s/alcohol | C6: Agua purificada | D6: 190 | E6: =IFERROR(IF($C6="","",INDEX(INSUMOS!$G$5:$G$84,MATCH($C6,INSUMOS!$B$5:$B$84,0))),"") | F6: =IFERROR(IF($C6="","",INDEX(INSUMOS!$I$5:$I$84,MATCH($C6,INSUMOS!$B$5:$B$84,0))),"") | G6: =IFERROR(IF($C6="","",$D6*$F6),"") | I6: =IF($B6="","",SUMIFS(VENTAS!$D$5:$D$504,VENTAS!$B$5:$B$504,INICIO!$C$8,VENTAS!$C$5:$C$504,$B6)) | J6: =IF($C6="","",$D6*$I6)
A7: 3 | B7: Coco s/alcohol | C7: Energia maquina granizadora | D7: 1 | E7: =IFERROR(IF($C7="","",INDEX(INSUMOS!$G$5:$G$84,MATCH($C7,INSUMOS!$B$5:$B$84,0))),"") | F7: =IFERROR(IF($C7="","",INDEX(INSUMOS!$I$5:$I$84,MATCH($C7,INSUMOS!$B$5:$B$84,0))),"") | G7: =IFERROR(IF($C7="","",$D7*$F7),"") | I7: =IF($B7="","",SUMIFS(VENTAS!$D$5:$D$504,VENTAS!$B$5:$B$504,INICIO!$C$8,VENTAS!$C$5:$C$504,$B7)) | J7: =IF($C7="","",$D7*$I7)
