Workbook

Sheet INSTRUCCIONES
B2: CANDYSHOTS — CALCULADORA DE COSTOS
B3: Agosto 2026 · Todo se recalcula solo. Tú solo tocas la columna de precios.
B6: CÓMO SE USA
B7: 1. Andá a la hoja INSUMOS. Es la lista de todo lo que se compra.
B8: 2. En la columna 'Precio de compra' pone lo que TE COSTÓ de verdad, con la factura en la mano.
B9: 3. En 'Cantidad que rinde' pone cuánto trae esa compra (gramos, ml, unidades).
B10: Ejemplo: comprás una libra de carne a $2.00 → Precio 2.00 · Cantidad 453.6 · Unidad g
B11: 4. Listo. Las hojas RECETAS y MENÚ se recalculan solas.
B13: LAS 3 HOJAS
B14: INSUMOS → Lista de compras. Acá ponés los precios reales. ES LA ÚNICA HOJA QUE TENÉS QUE LLENAR.
B15: RECETAS → Qué lleva cada plato y cuánto. Se puede agregar o quitar ingredientes libremente.
B16: MENÚ → Precio de venta, costo, food cost % y margen. Semáforo automático.
... B34: No hay ninguna bebida cargada porque no estaban en el menú que se pasó. Cuando las tengas se agregan.

Sheet INSUMOS
A1: INSUMOS — poné acá los precios reales de compra
A2: Solo tocás las columnas B y C. El costo unitario se calcula solo.
A4: INSUMO | B4: Precio de compra | C4: Cantidad que rinde | D4: Unidad | E4: COSTO UNITARIO | F4: Estado | G4: Nota
A5: — COMIDA —
A6: Papa | B6: 3.4 | C6: 1000 | D6: g | E6: =IFERROR(B6/C6,0) | F6: ✅ Confirmado
A7: Pollo crudo | B7: 5.53 | C7: 1000 | D7: g | E7: =IFERROR(B7/C7,0) | F7: ✅ Confirmado | G7: $0.83 por 150 g
A8: Carne molida | B8: 2 | C8: 453.6 | D8: g | E8: =IFERROR(B8/C8,0) | F8: ✅ Confirmado | G8: $2.00 la libra
A9: Pan de hamburguesa | B9: 2.85 | C9: 6 | D9: unidad | E9: =IFERROR(B9/C9,0) | F9: ✅ Confirmado | G9: Buscar uno más barato para la Clásica
A10: Cheddar laminado | B10: 6.15 | C10: 1000 | D10: g | E10: =IFERROR(B10/C10,0) | F10: ✅ Confirmado | G10: Lámina de 20 g = $0.12
A11: Huevo | B11: 1 | C11: 7 | D11: unidad | E11: =IFERROR(B11/C11,0) | F11: ✅ Confirmado
A12: Aro de cebolla congelado | B12: 6.62 | C12: 1000 | D12: g | E12: =IFERROR(B12/C12,0) | F12: ✅ Confirmado | G12: Aro de 25 g = $0.17
A13: Salchicha | B13: 0.35 | C13: 1 | D13: unidad | E13: =IFERROR(B13/C13,0) | F13: ✅ Confirmado
A14: Tocino | B14: 0.25 | C14: 25 | D14: g | E14: =IFERROR(B14/C14,0) | F14: ✅ Confirmado | G14: 1 tira ≈ 25 g
A15: Maduro | B15: 0.25 | C15: 1 | D15: unidad | E15: =IFERROR(B15/C15,0) | F15: ✅ Confirmado
A16: Guacamole | B16: 0.25 | C16: 1 | D16: porción | E16: =IFERROR(B16/C16,0) | F16: ✅ Confirmado | G16: 2 cucharadas
A17: Patacón | B17: 0.1 | C17: 1 | D17: unidad | E17: =IFERROR(B17/C17,0) | F17: ✅ Confirmado
A18: Chorizo | B18: 6.9 | C18: 1000 | D18: g | E18: =IFERROR(B18/C18,0) | F18: ⚠️ CONFIRMAR | G18: Estimado — el PDF lo marca como pendiente
A19: Cebolla caramelizada | B19: 0.16 | C19: 1 | D19: porción | E19: =IFERROR(B19/C19,0) | F19: ⚠️ CONFIRMAR | G19: Estimado
A20: Lechuga | B20: 0 | C20: 1 | D20: porción | E20: =IFERROR(B20/C20,0) | F20: ❌ FALTA | G20: Conseguir precio
A21: Tomate | B21: 0 | C21: 1 | D21: porción | E21: =IFERROR(B21/C21,0) | F21: ❌ FALTA | G21: Conseguir precio
A22: Salsas (porción) | B22: 0 | C22: 1 | D22: porción | E22: =IFERROR(B22/C22,0) | F22: ❌ FALTA | G22: Conseguir precio
A23: Apanado | B23: 0 | C23: 1 | D23: porción | E23: =IFERROR(B23/C23,0) | F23: ❌ FALTA | G23: Conseguir precio
A24: Aceite (por fritura) | B24: 0 | C24: 1 | D24: porción | E24: =IFERROR(B24/C24,0) | F24: ❌ FALTA | G24: Conseguir precio
A25: — EMPAQUE —
A26: Bandeja kraft | B26: 0.04 | C26: 1 | D26: unidad | E26: =IFERROR(B26/C26,0) | F26: ✅ Confirmado | G26: Consumo en el local
A27: Lonchera biodegradable 8" | B27: 0.23 | C27: 1 | D27: unidad | E27: =IFERROR(B27/C27,0) | F27: ✅ Confirmado | G27: Delivery
A28: Cono de papel | B28: 0 | C28: 1 | D28: unidad | E28: =IFERROR(B28/C28,0) | F28: ❌ FALTA | G28: Conseguir precio
A29: Vaso 12oz + tapa + pitillo | B29: 0.1 | C29: 1 | D29: set | E29: =IFERROR(B29/C29,0) | F29: ⚠️ CONFIRMAR | G29: Estimado de mayo
A30: — GRANIZADOS —
A31: Jarabe concentrado | B31: 10 | C31: 3785 | D31: ml | E31: =IFERROR(B31/C31,0) | F31: ⚠️ CONFIRMAR | G31: 1 galón · dilución 1:3 · 62.5 ml por vaso
A32: Hielo | B32: 0.75 | C32: 2268 | D32: g | E32: =IFERROR(B32/C32,0) | F32: ⚠️ CONFIRMAR | G32: Bolsa de 5 lb
A33: Leche entera | B33: 1 | C33: 1000 | D33: ml | E33: =IFERROR(B33/C33,0) | F33: ⚠️ CONFIRMAR | G33: Estimado de mayo
A34: Leche condensada | B34: 4.5 | C34: 1000 | D34: ml | E34: =IFERROR(B34/C34,0) | F34: ⚠️ CONFIRMAR | G34: Estimado de mayo
A35: Crema de leche | B35: 3 | C35: 1000 | D35: ml | E35: =IFERROR(B35/C35,0) | F35: ⚠️ CONFIRMAR | G35: Estimado de mayo
A36: Galleta Oreo | B36: 3.2 | C36: 36 | D36: unidad | E36: =IFERROR(B36/C36,0) | F36: ⚠️ CONFIRMAR | G36: Paquete de 36
A37: Nutella | B37: 16 | C37: 1000 | D37: g | E37: =IFERROR(B37/C37,0) | F37: ⚠️ CONFIRMAR | G37: Estimado de mayo
A38: Café soluble | B38: 20 | C38: 1000 | D38: g | E38: =IFERROR(B38/C38,0) | F38: ⚠️ CONFIRMAR | G38: Estimado de mayo
A39: Alcohol (aguardiente/vodka) | B39: 7 | C39: 750 | D39: ml | E39: =IFERROR(B39/C39,0) | F39: ⚠️ CONFIRMAR | G39: Porción de 30 ml
A40: — BEBIDAS —
A41: Cola | B41: 0 | C41: 1 | D41: unidad | E41: =IFERROR(B41/C41,0) | F41: ❌ FALTA | G41: No estaba en el menú entregado
...

Sheet RECETAS
A1: RECETAS — qué lleva cada producto
A2: Podés agregar o borrar filas. El nombre del producto debe coincidir EXACTO con la hoja MENÚ.
A4: PRODUCTO | B4: INSUMO | C4: Cantidad | D4: Unidad | E4: COSTO
A5: Bandeja Clásica | B5: Papa | C5: 150 | D5: g | E5: =IFERROR(C5*VLOOKUP(B5,INSUMOS!$A$5:$E$43,5,FALSE),0)
B6: Pollo crudo | C6: 150 | D6: g | E6: =IFERROR(C6*VLOOKUP(B6,INSUMOS!$A$5:$E$43,5,FALSE),0)
B7: Salchicha | C7: 1 | D7: unidad | E7: =IFERROR(C7*VLOOKUP(B7,INSUMOS!$A$5:$E$43,5,FALSE),0)
B8: Bandeja kraft | C8: 1 | D8: unidad | E8: =IFERROR(C8*VLOOKUP(B8,INSUMOS!$A$5:$E$43,5,FALSE),0)
B9: AJUSTE: extras sin costear | C9: 0.44 | D9: $ | E9: =IFERROR(C9*VLOOKUP(B9,INSUMOS!$A$5:$E$43,5,FALSE),0)
A10: Bandeja Completa | B10: Papa | C10: 150 | D10: g | E10: =IFERROR(C10*VLOOKUP(B10,INSUMOS!$A$5:$E$43,5,FALSE),0)
B11: Pollo crudo | C11: 150 | D11: g | E11: =IFERROR(C11*VLOOKUP(B11,INSUMOS!$A$5:$E$43,5,FALSE),0)
B12: Tocino | C12: 25 | D12: g | E12: =IFERROR(C12*VLOOKUP(B12,INSUMOS!$A$5:$E$43,5,FALSE),0)
B13: Maduro | C13: 1 | D13: unidad | E13: =IFERROR(C13*VLOOKUP(B13,INSUMOS!$A$5:$E$43,5,FALSE),0)
B14: Bandeja kraft | C14: 1 | D14: unidad | E14: =IFERROR(C14*VLOOKUP(B14,INSUMOS!$A$5:$E$43,5,FALSE),0)
B15: AJUSTE: extras sin costear | C15: 0.49 | D15: $ | E15: =IFERROR(C15*VLOOKUP(B15,INSUMOS!$A$5:$E$43,5,FALSE),0)
A16: Bandeja Suprema | B16: Papa | C16: 150 | D16: g | E16: =IFERROR(C16*VLOOKUP(B16,INSUMOS!$A$5:$E$43,5,FALSE),0)
B17: Pollo crudo | C17: 150 | D17: g | E17: =IFERROR(C17*VLOOKUP(B17,INSUMOS!$A$5:$E$43,5,FALSE),0)
B18: Salchicha | C18: 1 | D18: unidad | E18: =IFERROR(C18*VLOOKUP(B18,INSUMOS!$A$5:$E$43,5,FALSE),0)
B19: Tocino | C19: 25 | D19: g | E19: =IFERROR(C19*VLOOKUP(B19,INSUMOS!$A$5:$E$43,5,FALSE),0)
B20: Maduro | C20: 1 | D20: unidad | E20: =IFERROR(C20*VLOOKUP(B20,INSUMOS!$A$5:$E$43,5,FALSE),0)
B21: Guacamole | C21: 1 | D21: porción | E21: =IFERROR(C21*VLOOKUP(B21,INSUMOS!$A$5:$E$43,5,FALSE),0)
B22: Patacón | C22: 1 | D22: unidad | E22: =IFERROR(C22*VLOOKUP(B22,INSUMOS!$A$5:$E$43,5,FALSE),0)
B23: Bandeja kraft | C23: 1 | D23: unidad | E23: =IFERROR(C23*VLOOKUP(B23,INSUMOS!$A$5:$E$43,5,FALSE),0)
B24: AJUSTE: extras sin costear | C24: 0.54 | D24: $ | E24: =IFERROR(C24*VLOOKUP(B24,INSUMOS!$A$5:$E$43,5,FALSE),0)
A25: Solitaria de Pollo | B25: Papa | C25: 180 | D25: g | E25: =IFERROR(C25*VLOOKUP(B25,INSUMOS!$A$5:$E$43,5,FALSE),0)
B26: Pollo crudo | C26: 60 | D26: g | E26: =IFERROR(C26*VLOOKUP(B26,INSUMOS!$A$5:$E$43,5,FALSE),0)
B27: Cheddar laminado | C27: 25 | D27: g | E27: =IFERROR(C27*VLOOKUP(B27,INSUMOS!$A$5:$E$43,5,FALSE),0)
B28: AJUSTE: extras sin costear | C28: 0.4 | D28: $ | E28: =IFERROR(C28*VLOOKUP(B28,INSUMOS!$A$5:$E$43,5,FALSE),0)
A29: Solitaria de Chorizo | B29: Papa | C29: 180 | D29: g | E29: =IFERROR(C29*VLOOKUP(B29,INSUMOS!$A$5:$E$43,5,FALSE),0)
B30: Chorizo | C30: 60 | D30: g | E30: =IFERROR(C30*VLOOKUP(B30,INSUMOS!$A$5:$E$43,5,FALSE),0)
B31: Cheddar laminado | C31: 25 | D31: g | E31: =IFERROR(C31*VLOOKUP(B31,INSUMOS!$A$5:$E$43,5,FALSE),0)
B32: AJUSTE: extras sin costear | C32: 0.4 | D32: $ | E32: =IFERROR(C32*VLOOKUP(B32,INSUMOS!$A$5:$E$43,5,FALSE),0)
A33: Pollo Bacon | B33: Papa | C33: 200 | D33: g | E33: =IFERROR(C33*VLOOKUP(B33,INSUMOS!$A$5:$E$43,5,FALSE),0)
B34: Pollo crudo | C34: 60 | D34: g | E34: =IFERROR(C34*VLOOKUP(B34,INSUMOS!$A$5:$E$43,5,FALSE),0)
B35: Tocino | C35: 25 | D35: g | E35: =IFERROR(C35*VLOOKUP(B35,INSUMOS!$A$5:$E$43,5,FALSE),0)
B36: Cheddar laminado | C36: 30 | D36: g | E36: =IFERROR(C36*VLOOKUP(B36,INSUMOS!$A$5:$E$43,5,FALSE),0)
B37: AJUSTE: extras sin costear | C37: 0.41 | D37: $ | E37: =IFERROR(C37*VLOOKUP(B37,INSUMOS!$A$5:$E$43,5,FALSE),0)
A38: Chori Bacon | B38: Papa | C38: 200 | D38: g | E38: =IFERROR(C38*VLOOKUP(B38,INSUMOS!$A$5:$E$43,5,FALSE),0)
B39: Chorizo | C39: 50 | D39: g | E39: =IFERROR(C39*VLOOKUP(B39,INSUMOS!$A$5:$E$43,5,FALSE),0)
B40: Tocino | C40: 25 | D40: g | E40: =IFERROR(C40*VLOOKUP(B40,INSUMOS!$A$5:$E$43,5,FALSE),0)
B41: Cheddar laminado | C41: 30 | D41: g | E41: =IFERROR(C41*VLOOKUP(B41,INSUMOS!$A$5:$E$43,5,FALSE),0)
...

Sheet MENÚ
A1: MENÚ — precio, costo y margen
A2: Solo tocás la columna PVP. Todo lo demás se calcula solo. Techo sano de food cost: 35%.
A4: CATEGORÍA | B4: PRODUCTO | C4: PVP | D4: COSTO | E4: FOOD COST | F4: MARGEN $ | G4: SEMÁFORO
A5: GRANIZADOS DE MÁQUINA | B5: Granizado de Máquina (sin alcohol) | C5: 1.5 | D5: =SUMIF(RECETAS!$A$5:$A$184,$B5,RECETAS!$E$5:$E$184) | E5: =IF(OR($C5="",$C5=0),"",$D5/$C5) | F5: =IF($C5="","",$C5-$D5) | G5: =IF($E5="","",IF($E5<=0.3,"✅ SANO",IF($E5<=0.35,"🟡 LÍMITE","🔴 REVISAR")))
A6: GRANIZADOS DE MÁQUINA | B6: Granizado de Máquina (con alcohol) | C6: 2 | D6: =SUMIF(RECETAS!$A$5:$A$184,$B6,RECETAS!$E$5:$E$184) | E6: =IF(OR($C6="",$C6=0),"",$D6/$C6) | F6: =IF($C6="","",$C6-$D6) | G6: =IF($E6="","",IF($E6<=0.3,"✅ SANO",IF($E6<=0.35,"🟡 LÍMITE","🔴 REVISAR")))
A7: GRANIZADOS ESPECIALES | B7: Especial Oreo (sin alcohol) | C7: 3 | D7: =SUMIF(RECETAS!$A$5:$A$184,$B7,RECETAS!$E$5:$E$184) | E7: =IF(OR($C7="",$C7=0),"",$D7/$C7) | F7: =IF($C7="","",$C7-$D7) | G7: =IF($E7="","",IF($E7<=0.3,"✅ SANO",IF($E7<=0.35,"🟡 LÍMITE","🔴 REVISAR")))
A8: GRANIZADOS ESPECIALES | B8: Especial Oreo (con alcohol) | C8: 3.5 | D8: =SUMIF(RECETAS!$A$5:$A$184,$B8,RECETAS!$E$5:$E$184) | E8: =IF(OR($C8="",$C8=0),"",$D8/$C8) | F8: =IF($C8="","",$C8-$D8) | G8: =IF($E8="","",IF($E8<=0.3,"✅ SANO",IF($E8<=0.35,"🟡 LÍMITE","🔴 REVISAR")))
A9: GRANIZADOS ESPECIALES | B9: Especial Nutella (sin alcohol) | C9: 3 | D9: =SUMIF(RECETAS!$A$5:$A$184,$B9,RECETAS!$E$5:$E$184) | E9: =IF(OR($C9="",$C9=0),"",$D9/$C9) | F9: =IF($C9="","",$C9-$D9) | G9: =IF($E9="","",IF($E9<=0.3,"✅ SANO",IF($E9<=0.35,"🟡 LÍMITE","🔴 REVISAR")))
A10: GRANIZADOS ESPECIALES | B10: Especial Nutella (con alcohol) | C10: 3.5 | D10: =SUMIF(RECETAS!$A$5:$A$184,$B10,RECETAS!$E$5:$E$184) | E10: =IF(OR($C10="",$C10=0),"",$D10/$C10) | F10: =IF($C10="","",$C10-$D10) | G10: =IF($E10="","",IF($E10<=0.3,"✅ SANO",IF($E10<=0.35,"🟡 LÍMITE","🔴 REVISAR")))
A11: GRANIZADOS ESPECIALES | B11: Especial Café (sin alcohol) | C11: 3 | D11: =SUMIF(RECETAS!$A$5:$A$184,$B11,RECETAS!$E$5:$E$184) | E11: =IF(OR($C11="",$C11=0),"",$D11/$C11) | F11: =IF($C11="","",$C11-$D11) | G11: =IF($E11="","",IF($E11<=0.3,"✅ SANO",IF($E11<=0.35,"🟡 LÍMITE","🔴 REVISAR")))
A12: GRANIZADOS ESPECIALES | B12: Especial Café (con alcohol) | C12: 3.5 | D12: =SUMIF(RECETAS!$A$5:$A$184,$B12,RECETAS!$E$5:$E$184) | E12: =IF(OR($C12="",$C12=0),"",$D12/$C12) | F12: =IF($C12="","",$C12-$D12) | G12: =IF($E12="","",IF($E12<=0.3,"✅ SANO",IF($E12<=0.35,"🟡 LÍMITE","🔴 REVISAR")))
A13: BANDEJAS | B13: Bandeja Clásica | C13: 3.5 | D13: =SUMIF(RECETAS!$A$5:$A$184,$B13,RECETAS!$E$5:$E$184) | E13: =IF(OR($C13="",$C13=0),"",$D13/$C13) | F13: =IF($C13="","",$C13-$D13) | G13: =IF($E13="","",IF($E13<=0.3,"✅ SANO",IF($E13<=0.35,"🟡 LÍMITE","🔴 REVISAR")))
A14: BANDEJAS | B14: Bandeja Completa | C14: 4.5 | D14: =SUMIF(RECETAS!$A$5:$A$184,$B14,RECETAS!$E$5:$E$184) | E14: =IF(OR($C14="",$C14=0),"",$D14/$C14) | F14: =IF($C14="","",$C14-$D14) | G14: =IF($E14="","",IF($E14<=0.3,"✅ SANO",IF($E14<=0.35,"🟡 LÍMITE","🔴 REVISAR")))
A15: BANDEJAS | B15: Bandeja Suprema | C15: 5.5 | D15: =SUMIF(RECETAS!$A$5:$A$184,$B15,RECETAS!$E$5:$E$184) | E15: =IF(OR($C15="",$C15=0),"",$D15/$C15) | F15: =IF($C15="","",$C15-$D15) | G15: =IF($E15="","",IF($E15<=0.3,"✅ SANO",IF($E15<=0.35,"🟡 LÍMITE","🔴 REVISAR")))
A16: CONOS — SOLITARIAS | B16: Solitaria de Pollo | C16: 2.75 | D16: =SUMIF(RECETAS!$A$5:$A$184,$B16,RECETAS!$E$5:$E$184) | E16: =IF(OR($C16="",$C16=0),"",$D16/$C16) | F16: =IF($C16="","",$C16-$D16) | G16: =IF($E16="","",IF($E16<=0.3,"✅ SANO",IF($E16<=0.35,"🟡 LÍMITE","🔴 REVISAR")))
... A30: ADICIONALES | B30: Adicional: Doble carne | C30: 1.5 | D30: =SUMIF(RECETAS!$A$5:$A$184,$B30,RECETAS!$E$5:$E$184) | E30: =IF(OR($C30="",$C30=0),"",$D30/$C30) | F30: =IF($C30="","",$C30-$D30) | G30: =IF($E30="","",IF($E30<=0.3,"✅ SANO",IF($E30<=0.35,"🟡 LÍMITE","🔴 REVISAR")))
A31: BEBIDAS | D31: =SUMIF(RECETAS!$A$5:$A$184,$B31,RECETAS!$E$5:$E$184) | E31: =IF(OR($C31="",$C31=0),"",$D31/$C31) | F31: =IF($C31="","",$C31-$D31) | G31: =IF($E31="","",IF($E31<=0.3,"✅ SANO",IF($E31<=0.35,"🟡 LÍMITE","🔴 REVISAR")))
D32: =IF($B32="","",SUMIF(RECETAS!$A$5:$A$184,$B32,RECETAS!$E$5:$E$184)) | E32: =IF(OR($C32="",$C32=0),"",$D32/$C32) | F32: =IF($C32="","",$C32-$D32) | G32: =IF($E32="","",IF($E32<=0.3,"✅ SANO",IF($E32<=0.35,"🟡 LÍMITE","🔴 REVISAR")))
D33: =IF($B33="","",SUMIF(RECETAS!$A$5:$A$184,$B33,RECETAS!$E$5:$E$184)) | E33: =IF(OR($C33="",$C33=0),"",$D33/$C33) | F33: =IF($C33="","",$C33-$D33) | G33: =IF($E33="","",IF($E33<=0.3,"✅ SANO",IF($E33<=0.35,"🟡 LÍMITE","🔴 REVISAR")))
D34: =IF($B34="","",SUMIF(RECETAS!$A$5:$A$184,$B34,RECETAS!$E$5:$E$184)) | E34: =IF(OR($C34="",$C34=0),"",$D34/$C34) | F34: =IF($C34="","",$C34-$D34) | G34: =IF($E34="","",IF($E34<=0.3,"✅ SANO",IF($E34<=0.35,"🟡 LÍMITE","🔴 REVISAR")))
D35: =IF($B35="","",SUMIF(RECETAS!$A$5:$A$184,$B35,RECETAS!$E$5:$E$184)) | E35: =IF(OR($C35="",$C35=0),"",$D35/$C35) | F35: =IF($C35="","",$C35-$D35) | G35: =IF($E35="","",IF($E35<=0.3,"✅ SANO",IF($E35<=0.35,"🟡 LÍMITE","🔴 REVISAR")))
D36: =IF($B36="","",SUMIF(RECETAS!$A$5:$A$184,$B36,RECETAS!$E$5:$E$184)) | E36: =IF(OR($C36="",$C36=0),"",$D36/$C36) | F36: =IF($C36="","",$C36-$D36) | G36: =IF($E36="","",IF($E36<=0.3,"✅ SANO",IF($E36<=0.35,"🟡 LÍMITE","🔴 REVISAR")))
D37: =IF($B37="","",SUMIF(RECETAS!$A$5:$A$184,$B37,RECETAS!$E$5:$E$184)) | E37: =IF(OR($C37="",$C37=0),"",$D37/$C37) | F37: =IF($C37="","",$C37-$D37) | G37: =IF($E37="","",IF($E37<=0.3,"✅ SANO",IF($E37<=0.35,"🟡 LÍMITE","🔴 REVISAR")))
D38: =IF($B38="","",SUMIF(RECETAS!$A$5:$A$184,$B38,RECETAS!$E$5:$E$184)) | E38: =IF(OR($C38="",$C38=0),"",$D38/$C38) | F38: =IF($C38="","",$C38-$D38) | G38: =IF($E38="","",IF($E38<=0.3,"✅ SANO",IF($E38<=0.35,"🟡 LÍMITE","🔴 REVISAR")))
D39: =IF($B39="","",SUMIF(RECETAS!$A$5:$A$184,$B39,RECETAS!$E$5:$E$184)) | E39: =IF(OR($C39="",$C39=0),"",$D39/$C39) | F39: =IF($C39="","",$C39-$D39) | G39: =IF($E39="","",IF($E39<=0.3,"✅ SANO",IF($E39<=0.35,"🟡 LÍMITE","🔴 REVISAR")))
D40: =IF($B40="","",SUMIF(RECETAS!$A$5:$A$184,$B40,RECETAS!$E$5:$E$184)) | E40: =IF(OR($C40="",$C40=0),"",$D40/$C40) | F40: =IF($C40="","",$C40-$D40) | G40: =IF($E40="","",IF($E40<=0.3,"✅ SANO",IF($E40<=0.35,"🟡 LÍMITE","🔴 REVISAR")))
D41: =IF($B41="","",SUMIF(RECETAS!$A$5:$A$184,$B41,RECETAS!$E$5:$E$184)) | E41: =IF(OR($C41="",$C41=0),"",$D41/$C41) | F41: =IF($C41="","",$C41-$D41) | G41: =IF($E41="","",IF($E41<=0.3,"✅ SANO",IF($E41<=0.35,"🟡 LÍMITE","🔴 REVISAR")))
D42: =IF($B42="","",SUMIF(RECETAS!$A$5:$A$184,$B42,RECETAS!$E$5:$E$184)) | E42: =IF(OR($C42="",$C42=0),"",$D42/$C42) | F42: =IF($C42="","",$C42-$D42) | G42: =IF($E42="","",IF($E42<=0.3,"✅ SANO",IF($E42<=0.35,"🟡 LÍMITE","🔴 REVISAR")))
D43: =IF($B43="","",SUMIF(RECETAS!$A$5:$A$184,$B43,RECETAS!$E$5:$E$184)) | E43: =IF(OR($C43="",$C43=0),"",$D43/$C43) | F43: =IF($C43="","",$C43-$D43) | G43: =IF($E43="","",IF($E43<=0.3,"✅ SANO",IF($E43<=0.35,"🟡 LÍMITE","🔴 REVISAR")))
